Workbook
Name w: #REF!
Name 과일양: #REF!
Name 과일양: #REF!
Name 과일양: #REF!
Name 과일양: #REF!
Name 과일양: #REF!
Name 요약: '[1]물류비 내역서'!$B$4:$G$121
Name 요약: #REF!
Name 요약: '물류비 내역서'!$B$4:$G$145
Name 월생산일수: #REF!
Name 월생산일수: #REF!
Name 월생산일수: #REF!
Name 월생산일수: #REF!
Name 월생산일수: #REF!
Name 입고예정서: #REF!
Name 입고예정서: #REF!
Name 입고예정서: #REF!
Name 입고예정서: #REF!
Name 입고예정서: #REF!

Sheet 물류비 청구서
B1: ( 8 ) 월 물류비 청구서
P5: 발 신 | T5: 아워박스 ㈜
B6: 수 신 | F6: ㈜ 농협목우촌 이커머스사업부 | P6: 대 표 | T6: 박 철 수 (인)
P7: 사 업 장 소 재 지 | T7: 서울시 구로구 디지털로288, 908호(구로동, 대륭포스트타워 1차)
B9: 아래와 같이 청구합니다. | P9: 전 화 | T9: 1588-9213
P10: 팩 스 | T10: 02-837-9507
O12: 기 간 | R12: : | S12: 2026년 8월 1일 ~ 2026년 8월 31일
B13: 공급가액 | H13: =O18+O42+O52+O72+O74+O76+O81 -> 2.7193698e+08 | O13: 원 정 | R13: ( \ | T13: =Y18+Y42+Y52+Y72+Y74+Y76+Y81 -> 2.9913068e+08 | AC13: )
B14: 세 액 | H14: =T18+T42+T52+T72+T74+T76+T81 -> 27193698
B15: 구 분 | H15: 수 량 | K15: 단 가 | O15: 공급가액 | T15: 세 액 | Y15: 합 계
B16: 보관료_상온 | H16: ='물류비 내역서'!C5 -> 124 | K16: ='물류비 내역서'!D5 -> 20000 | O16: =H16*K16 -> 2480000 | T16: =+O16*0.1 -> 248000 | Y16: =O16+T16 -> 2728000
B17: 보관료_저온 | H17: ='물류비 내역서'!C6 -> 248 | K17: ='물류비 내역서'!D6 -> 27000 | O17: =H17*K17 -> 6696000 | T17: =+O17*0.1 -> 669600 | Y17: =O17+T17 -> 7365600
B18: 소 계 (보 관 료) | O18: =SUM(O16:S17) -> 9176000 | T18: =SUM(T16:X17) -> 917600 | Y18: =SUM(Y16:AC17) -> 10093600
B19: 아이스박스_2K | H19: ='물류비 내역서'!C7+'물류비 내역서'!Q5+'물류비 내역서'!J5 -> 4 | K19: ='물류비 내역서'!D7 -> 420 | O19: =H19*K19 -> 1680 | T19: =+O19*0.1 -> 168 | Y19: =O19+T19 -> 1848
B20: 아이스박스_1호 | H20: ='물류비 내역서'!C8+'물류비 내역서'!J6+'물류비 내역서'!Q6 -> 26173 | K20: ='물류비 내역서'!D8 -> 550 | O20: =H20*K20 -> 14395150 | T20: =+O20*0.1 -> 1439515 | Y20: =O20+T20 -> 15834665
B21: 아이스박스_T135 | H21: ='물류비 내역서'!C9+'물류비 내역서'!J7+'물류비 내역서'!Q7 -> 6782 | K21: ='물류비 내역서'!D9 -> 650 | O21: =H21*K21 -> 4408300 | T21: =+O21*0.1 -> 440830 | Y21: =O21+T21 -> 4849130
B22: 아이스박스_2호 | H22: ='물류비 내역서'!C10+'물류비 내역서'!J8+'물류비 내역서'!Q8 -> 4483 | K22: ='물류비 내역서'!D10 -> 750 | O22: =H22*K22 -> 3362250 | T22: =+O22*0.1 -> 336225 | Y22: =O22+T22 -> 3698475
B23: 아이스박스_3호 | H23: ='물류비 내역서'!C11+'물류비 내역서'!J9+'물류비 내역서'!Q9 -> 11969 | K23: ='물류비 내역서'!D11 -> 1000 | O23: =H23*K23 -> 11969000 | T23: =+O23*0.1 -> 1196900 | Y23: =O23+T23 -> 13165900
B24: 아이스박스_4호 | H24: ='물류비 내역서'!C12+'물류비 내역서'!J10+'물류비 내역서'!Q10 -> 1347 | K24: ='물류비 내역서'!D12 -> 1350 | O24: =H24*K24 -> 1818450 | T24: =+O24*0.1 -> 181845 | Y24: =O24+T24 -> 2000295
B25: 아이스박스_5호 | H25: ='물류비 내역서'!C13+'물류비 내역서'!Q11 -> 580 | K25: ='물류비 내역서'!D13 -> 1750 | O25: =H25*K25 -> 1015000 | T25: =+O25*0.1 -> 101500 | Y25: =O25+T25 -> 1116500
B26: 아이스박스_6호 | H26: ='물류비 내역서'!C14+'물류비 내역서'!Q12 -> 154 | K26: ='물류비 내역서'!D14 -> 1950 | O26: =H26*K26 -> 300300 | T26: =+O26*0.1 -> 30030 | Y26: =O26+T26 -> 330330
B27: 아이스박스_7호 | H27: ='물류비 내역서'!C15+'물류비 내역서'!Q13 -> 84 | K27: ='물류비 내역서'!D15 -> 2500 | O27: =H27*K27 -> 210000 | T27: =+O27*0.1 -> 21000 | Y27: =O27+T27 -> 231000
B28: 종이박스_1호 | H28: ='물류비 내역서'!C16+'물류비 내역서'!J11+'물류비 내역서'!Q14 -> 6268 | K28: ='물류비 내역서'!D16 -> 210 | O28: =H28*K28 -> 1316280 | T28: =+O28*0.1 -> 131628 | Y28: =O28+T28 -> 1447908
B29: 종이박스_2호 | H29: ='물류비 내역서'!C17+'물류비 내역서'!J12+'물류비 내역서'!Q15 -> 719 | K29: ='물류비 내역서'!D17 -> 330 | O29: =H29*K29 -> 237270 | T29: =+O29*0.1 -> 23727 | Y29: =O29+T29 -> 260997
B30: 종이박스_2호(강) | H30: ='물류비 내역서'!C18+'물류비 내역서'!J13+'물류비 내역서'!Q16 -> 0 | K30: ='물류비 내역서'!D18 -> 370 | O30: =H30*K30 -> 0 | T30: =+O30*0.1 -> 0 | Y30: =O30+T30 -> 0
B31: 종이박스_3호 | H31: ='물류비 내역서'!C19+'물류비 내역서'!J14+'물류비 내역서'!Q17 -> 154 | K31: ='물류비 내역서'!D19 -> 540 | O31: =H31*K31 -> 83160 | T31: =+O31*0.1 -> 8316 | Y31: =O31+T31 -> 91476
B32: 종이박스_4호 | H32: ='물류비 내역서'!C20+'물류비 내역서'!Q18 -> 3 | K32: ='물류비 내역서'!D20 -> 700 | O32: =H32*K32 -> 2100 | T32: =+O32*0.1 -> 210 | Y32: =O32+T32 -> 2310
B33: 종이박스_5호 | H33: ='물류비 내역서'!C21+'물류비 내역서'!Q19 -> 0 | K33: ='물류비 내역서'!D21 -> 1100 | O33: =H33*K33 -> 0 | T33: =+O33*0.1 -> 0 | Y33: =O33+T33 -> 0
B34: 아이스팩_500g | H34: ='물류비 내역서'!C22+'물류비 내역서'!J15+'물류비 내역서'!Q20 -> 38030 | K34: 150 | O34: =H34*K34 -> 5704500 | T34: =+O34*0.1 -> 570450 | Y34: =O34+T34 -> 6274950
B35: 아이스팩_1000g | H35: ='물류비 내역서'!C23+'물류비 내역서'!J16+'물류비 내역서'!Q21 -> 30995 | K35: 250 | O35: =H35*K35 -> 7748750 | T35: =+O35*0.1 -> 774875 | Y35: =O35+T35 -> 8523625
B36: ='물류비 내역서'!B25 -> 드라이아이스 | H36: ='물류비 내역서'!C25+'물류비 내역서'!J18+'물류비 내역서'!Q22 -> 0 | K36: 480 | O36: =H36*K36 -> 0 | T36: =+O36*0.1 -> 0 | Y36: =O36+T36 -> 0
B37: PCM | H37: ='물류비 내역서'!C24+'물류비 내역서'!J17+'물류비 내역서'!Q23 -> 125512 | K37: 250 | O37: =H37*K37 -> 31378000 | T37: =+O37*0.1 -> 3137800 | Y37: =O37+T37 -> 34515800
B38: 에어캡 | H38: ='물류비 내역서'!C27+'물류비 내역서'!Q24 -> 1969 | K38: 60 | O38: =H38*K38 -> 118140 | T38: =+O38*0.1 -> 11814 | Y38: =O38+T38 -> 129954
B39: 인쇄물 작업 | H39: ='물류비 내역서'!C28+'물류비 내역서'!Q25 -> 27 | K39: 100 | O39: =H39*K39 -> 2700 | T39: =+O39*0.1 -> 270 | Y39: =O39+T39 -> 2970
B40: 폼텍라벨/제작비용 | H40: =일반!AR36 -> 0 | K40: 100 | O40: =H40*K40 -> 0 | T40: =+O40*0.1 -> 0 | Y40: =O40+T40 -> 0
B41: ='물류비 내역서'!B29 -> 신선테이핑 작업 | H41: ='물류비 내역서'!C29+'물류비 내역서'!Q27 -> 42 | K41: 150 | O41: =H41*K41 -> 6300 | T41: =+O41*0.1 -> 630 | Y41: =O41+T41 -> 6930
B42: 소 계 (부 자 재) | O42: =SUM(O19:S41) -> 84077330 | T42: =SUM(T19:X41) -> 8407733 | Y42: =SUM(Y19:AC41) -> 92485063
B43: 작업료_골라담기 | H43: ='물류비 내역서'!C30+'물류비 내역서'!Q28 -> 20767 | K43: 900 | O43: =H43*K43 -> 18690300 | T43: =+O43*0.1 -> 1869030 | Y43: =O43+T43 -> 20559330
B44: 작업료_세트/홈쇼핑 | H44: ='물류비 내역서'!C31+'물류비 내역서'!J19+'물류비 내역서'!Q29 -> 38060 | K44: 450 | O44: =H44*K44 -> 17127000 | T44: =+O44*0.1 -> 1712700 | Y44: =O44+T44 -> 18839700
B45: ='물류비 내역서'!B32 -> 작업료_부직포세트 | H45: ='물류비 내역서'!C32+'물류비 내역서'!Q30 -> 12 | K45: 700 | O45: =H45*K45 -> 8400 | T45: =+O45*0.1 -> 840 | Y45: =O45+T45 -> 9240
...

Sheet 물류비 내역서
B2: 요 약 (일반) | I2: 요 약 (홈쇼핑) | P2: 요 약 (도착보장)
G3: [ VAT 포함 ] | N3: [ VAT 포함 ] | U3: [ VAT 포함 ]
B4: 품명 | C4: 수량 | D4: 단가 | E4: 공급가액 | F4: 세액 | G4: 합계액 | I4: 품명 | J4: 수량 | K4: 단가 | L4: 공급가액 | M4: 세액 | N4: 합계액 | P4: 품명 | Q4: 수량 | R4: 단가 | S4: 공급가액 | T4: 세액 | U4: 합계액
B5: 보관료_상온 | C5: =보관료_합계!C37 -> 124 | D5: 20000 | E5: =C5*D5 -> 2480000 | F5: =E5*0.1 -> 248000 | G5: =SUM(E5:F5) -> 2728000 | I5: 홈쇼핑_아이스박스_2K | J5: =홈쇼핑!AA35 -> 4 | K5: 420 | L5: =J5*K5 -> 1680 | M5: =L5*0.1 -> 168 | N5: =SUM(L5:M5) -> 1848 | P5: =도착보장!B2 -> 도착_아이스박스_2K | Q5: =도착보장!B36 -> 0 | R5: 420 | S5: =Q5*R5 -> 0 | T5: =S5*0.1 -> 0 | U5: =SUM(S5:T5) -> 0
B6: 보관료_저온 | C6: =보관료_합계!D37+보관료_합계!E37 -> 248 | D6: 27000 | E6: =C6*D6 -> 6696000 | F6: =E6*0.1 -> 669600 | G6: =SUM(E6:F6) -> 7365600 | I6: 홈쇼핑_아이스박스_1호 | J6: =홈쇼핑!B35+홈쇼핑!C35+홈쇼핑!AB35+홈쇼핑!AC35 -> 6 | K6: 550 | L6: =J6*K6 -> 3300 | M6: =L6*0.1 -> 330 | N6: =SUM(L6:M6) -> 3630 | P6: =도착보장!C2 -> 도착_아이스박스_1호 | Q6: =도착보장!C36+도착보장!K36 -> 11598 | R6: 550 | S6: =Q6*R6 -> 6378900 | T6: =S6*0.1 -> 637890 | U6: =SUM(S6:T6) -> 7016790
B7: =일반!B2 -> 일반_아이스박스_2K | C7: =일반!B36 -> 0 | D7: 420 | E7: =C7*D7 -> 0 | F7: =E7*0.1 -> 0 | G7: =SUM(E7:F7) -> 0 | I7: 홈쇼핑_아이스박스_T135 | J7: =홈쇼핑!D35+홈쇼핑!E35+홈쇼핑!AD35+홈쇼핑!AE35 -> 19 | K7: 650 | L7: =J7*K7 -> 12350 | M7: =L7*0.1 -> 1235 | N7: =SUM(L7:M7) -> 13585 | P7: =도착보장!D2 -> 도착_아이스박스_T135 | Q7: =도착보장!D36+도착보장!L36 -> 1984 | R7: 650 | S7: =Q7*R7 -> 1289600 | T7: =S7*0.1 -> 128960 | U7: =SUM(S7:T7) -> 1418560
B8: =일반!C2 -> 일반_아이스박스_1호 | C8: =일반!C36+일반!K36 -> 14569 | D8: 550 | E8: =C8*D8 -> 8012950 | F8: =E8*0.1 -> 801295 | G8: =SUM(E8:F8) -> 8814245 | I8: 홈쇼핑_아이스박스_2호 | J8: =홈쇼핑!F35+홈쇼핑!G35+홈쇼핑!AF35+홈쇼핑!AG35 -> 0 | K8: 750 | L8: =J8*K8 -> 0 | M8: =L8*0.1 -> 0 | N8: =SUM(L8:M8) -> 0 | P8: =도착보장!E2 -> 도착_아이스박스_2호 | Q8: =도착보장!E36+도착보장!M36 -> 2017 | R8: 750 | S8: =Q8*R8 -> 1512750 | T8: =S8*0.1 -> 151275 | U8: =SUM(S8:T8) -> 1664025
B9: =일반!D2 -> 일반_아이스박스_T135 | C9: =일반!D36+일반!L36 -> 4779 | D9: 650 | E9: =C9*D9 -> 3106350 | F9: =E9*0.1 -> 310635 | G9: =SUM(E9:F9) -> 3416985 | I9: 홈쇼핑_아이스박스_3호 | J9: =홈쇼핑!H35+홈쇼핑!I35+홈쇼핑!AH35+홈쇼핑!AI35 -> 25 | K9: 1000 | L9: =J9*K9 -> 25000 | M9: =L9*0.1 -> 2500 | N9: =SUM(L9:M9) -> 27500 | P9: =도착보장!F2 -> 도착_아이스박스_3호 | Q9: =도착보장!F36+도착보장!N36 -> 1885 | R9: 1000 | S9: =Q9*R9 -> 1885000 | T9: =S9*0.1 -> 188500 | U9: =SUM(S9:T9) -> 2073500
B10: =일반!E2 -> 일반_아이스박스_2호 | C10: =일반!E36+일반!M36 -> 2466 | D10: 750 | E10: =C10*D10 -> 1849500 | F10: =E10*0.1 -> 184950 | G10: =SUM(E10:F10) -> 2034450 | I10: 홈쇼핑_아이스박스_4호 | J10: =홈쇼핑!J35+홈쇼핑!K35+홈쇼핑!AJ35+홈쇼핑!AK35 -> 0 | K10: 1350 | L10: =J10*K10 -> 0 | M10: =L10*0.1 -> 0 | N10: =SUM(L10:M10) -> 0 | P10: =도착보장!G2 -> 도착_아이스박스_4호 | Q10: =도착보장!G36+도착보장!O36 -> 474 | R10: 1350 | S10: =Q10*R10 -> 639900 | T10: =S10*0.1 -> 63990 | U10: =SUM(S10:T10) -> 703890
B11: =일반!F2 -> 일반_아이스박스_3호 | C11: =일반!F36+일반!N36 -> 10059 | D11: 1000 | E11: =C11*D11 -> 10059000 | F11: =E11*0.1 -> 1005900 | G11: =SUM(E11:F11) -> 11064900 | I11: 홈쇼핑_종이박스_1호 | J11: =홈쇼핑!P35+홈쇼핑!AP35 -> 5 | K11: 210 | L11: =J11*K11 -> 1050 | M11: =L11*0.1 -> 105 | N11: =SUM(L11:M11) -> 1155 | P11: =도착보장!H2 -> 도착_아이스박스_5호 | Q11: =도착보장!H36+도착보장!P36 -> 240 | R11: 1750 | S11: =Q11*R11 -> 420000 | T11: =S11*0.1 -> 42000 | U11: =SUM(S11:T11) -> 462000
B12: =일반!G2 -> 일반_아이스박스_4호 | C12: =일반!G36+일반!O36 -> 873 | D12: 1350 | E12: =C12*D12 -> 1178550 | F12: =E12*0.1 -> 117855 | G12: =SUM(E12:F12) -> 1296405 | I12: 홈쇼핑_종이박스_2호 | J12: =홈쇼핑!Q35+홈쇼핑!AQ35 -> 0 | K12: 330 | L12: =J12*K12 -> 0 | M12: =L12*0.1 -> 0 | N12: =SUM(L12:M12) -> 0 | P12: =도착보장!I2 -> 도착_아이스박스_6호 | Q12: =도착보장!I36+도착보장!Q36+도착보장!AC36 -> 42 | R12: 1950 | S12: =Q12*R12 -> 81900 | T12: =S12*0.1 -> 8190 | U12: =SUM(S12:T12) -> 90090
B13: =일반!H2 -> 일반_아이스박스_5호 | C13: =일반!H36+일반!P36 -> 340 | D13: 1750 | E13: =C13*D13 -> 595000 | F13: =E13*0.1 -> 59500 | G13: =SUM(E13:F13) -> 654500 | I13: 홈쇼핑_종이박스_2호(강) | J13: 0 | K13: 370 | L13: =J13*K13 -> 0 | M13: =L13*0.1 -> 0 | N13: =SUM(L13:M13) -> 0 | P13: =도착보장!J2 -> 도착_아이스박스_7호 | Q13: =도착보장!J36+도착보장!R36+도착보장!AD36 -> 13 | R13: 2500 | S13: =Q13*R13 -> 32500 | T13: =S13*0.1 -> 3250 | U13: =SUM(S13:T13) -> 35750
B14: =일반!I2 -> 일반_아이스박스_6호 | C14: =일반!I36+일반!Q36+일반!AC36 -> 112 | D14: 1950 | E14: =C14*D14 -> 218400 | F14: =E14*0.1 -> 21840 | G14: =SUM(E14:F14) -> 240240 | I14: 홈쇼핑_종이박스_3호 | K14: 540 | L14: =J14*K14 -> 0 | M14: =L14*0.1 -> 0 | N14: =SUM(L14:M14) -> 0 | P14: =도착보장!T2 -> 도착_종이박스_1호 | Q14: =도착보장!T36 -> 2189 | R14: 210 | S14: =Q14*R14 -> 459690 | T14: =S14*0.1 -> 45969 | U14: =SUM(S14:T14) -> 505659
B15: =일반!J2 -> 일반_아이스박스_7호 | C15: =일반!J36+일반!R36+일반!AD36 -> 71 | D15: 2500 | E15: =C15*D15 -> 177500 | F15: =E15*0.1 -> 17750 | G15: =SUM(E15:F15) -> 195250 | I15: =홈쇼핑!AT2 -> 아이스팩_500g | J15: =홈쇼핑!AT35 -> 113 | K15: 150 | L15: =J15*K15 -> 16950 | M15: =L15*0.1 -> 1695 | N15: =SUM(L15:M15) -> 18645 | P15: =도착보장!U2 -> 도착_종이박스_2호 | Q15: =도착보장!U36 -> 375 | R15: 330 | S15: =Q15*R15 -> 123750 | T15: =S15*0.1 -> 12375 | U15: =SUM(S15:T15) -> 136125
B16: =일반!T2 -> 일반_종이박스_1호 | C16: =일반!T36 -> 4074 | D16: 210 | E16: =C16*D16 -> 855540 | F16: =E16*0.1 -> 85554 | G16: =SUM(E16:F16) -> 941094 | I16: =홈쇼핑!AU2 -> 아이스팩_1000g | J16: =홈쇼핑!AU35 -> 66 | K16: 250 | L16: =J16*K16 -> 16500 | M16: =L16*0.1 -> 1650 | N16: =SUM(L16:M16) -> 18150 | P16: =도착보장!V2 -> 도착_종이박스_2호(강) | Q16: =도착보장!V36 -> 0 | R16: 370 | S16: =Q16*R16 -> 0 | T16: =S16*0.1 -> 0 | U16: =SUM(S16:T16) -> 0
B17: =일반!U2 -> 일반_종이박스_2호 | C17: =일반!U36 -> 344 | D17: 330 | E17: =C17*D17 -> 113520 | F17: =E17*0.1 -> 11352 | G17: =SUM(E17:F17) -> 124872 | I17: =홈쇼핑!AV2 -> PCM | J17: =홈쇼핑!AV35 -> 109 | K17: 250 | L17: =J17*K17 -> 27250 | M17: =L17*0.1 -> 2725 | N17: =SUM(L17:M17) -> 29975 | P17: =도착보장!W2 -> 도착_종이박스_3호 | Q17: =도착보장!W36 -> 48 | R17: 540 | S17: =Q17*R17 -> 25920 | T17: =S17*0.1 -> 2592 | U17: =SUM(S17:T17) -> 28512
B18: =일반!V2 -> 일반_종이박스_2호 (강) | C18: =일반!V36 -> 0 | D18: 370 | E18: =C18*D18 -> 0 | F18: =E18*0.1 -> 0 | G18: =SUM(E18:F18) -> 0 | I18: =홈쇼핑!AW2 -> 드라이아이스 | J18: =홈쇼핑!AW35 -> 0 | K18: 480 | L18: =J18*K18 -> 0 | M18: =L18*0.1 -> 0 | N18: =SUM(L18:M18) -> 0 | P18: =도착보장!X2 -> 도착_종이박스_4호 | Q18: =도착보장!X36 -> 0 | R18: 700 | S18: =Q18*R18 -> 0 | T18: =S18*0.1 -> 0 | U18: =SUM(S18:T18) -> 0
B19: =일반!W2 -> 일반_종이박스_3호 | C19: =일반!W36 -> 106 | D19: 540 | E19: =C19*D19 -> 57240 | F19: =E19*0.1 -> 5724 | G19: =SUM(E19:F19) -> 62964 | I19: =일반!AV$2 -> 작업료_세트/홈쇼핑 | J19: =홈쇼핑!AY35 -> 96 | K19: 450 | L19: =J19*K19 -> 43200 | M19: =L19*0.1 -> 4320 | N19: =SUM(L19:M19) -> 47520 | P19: =도착보장!Y2 -> 도착_종이박스_5호 | Q19: =도착보장!Y36 -> 0 | R19: 1100 | S19: =Q19*R19 -> 0 | T19: =S19*0.1 -> 0 | U19: =SUM(S19:T19) -> 0
B20: =일반!X2 -> 일반_종이박스_4호 | C20: =일반!X36 -> 3 | D20: 700 | E20: =C20*D20 -> 2100 | F20: =E20*0.1 -> 210 | G20: =SUM(E20:F20) -> 2310 | I20: =홈쇼핑!BA2 -> 저온_택배비_극소 | J20: =홈쇼핑!BA35 -> 15 | K20: 2050 | L20: =J20*K20 -> 30750 | M20: =L20*0.1 -> 3075 | N20: =SUM(L20:M20) -> 33825 | P20: =도착보장!AL2 -> 도착_아이스팩_500g | Q20: =도착보장!AL36 -> 10946 | R20: 150 | S20: =Q20*R20 -> 1641900 | T20: =S20*0.1 -> 164190 | U20: =SUM(S20:T20) -> 1806090
B21: =일반!Y2 -> 일반_종이박스_5호 | C21: =일반!Y36 -> 0 | D21: 1100 | E21: =C21*D21 -> 0 | F21: =E21*0.1 -> 0 | G21: =SUM(E21:F21) -> 0 | I21: =홈쇼핑!BB2 -> 저온_택배비_소 | J21: =홈쇼핑!BB35 -> 25 | K21: 2550 | L21: =J21*K21 -> 63750 | M21: =L21*0.1 -> 6375 | N21: =SUM(L21:M21) -> 70125 | P21: =도착보장!AM2 -> 도착_아이스팩_1000g | Q21: =도착보장!AM36 -> 3012 | R21: 250 | S21: =Q21*R21 -> 753000 | T21: =S21*0.1 -> 75300 | U21: =SUM(S21:T21) -> 828300
B22: =일반!AL$2 -> 아이스팩_500g | C22: =일반!AL36 -> 26971 | D22: 150 | E22: =C22*D22 -> 4045650 | F22: =E22*0.1 -> 404565 | G22: =SUM(E22:F22) -> 4450215 | I22: =홈쇼핑!BC2 -> 상온_택배비_극소 | J22: =홈쇼핑!BC35 -> 5 | K22: 1800 | L22: =J22*K22 -> 9000 | M22: =L22*0.1 -> 900 | N22: =SUM(L22:M22) -> 9900 | P22: =도착보장!AO2 -> 도착_드라이아이스 | Q22: =도착보장!AO36 -> 0 | R22: 480 | S22: =Q22*R22 -> 0 | T22: =S22*0.1 -> 0 | U22: =SUM(S22:T22) -> 0
B23: =일반!AM$2 -> 아이스팩_1000g | C23: =일반!AM36 -> 27917 | D23: 250 | E23: =C23*D23 -> 6979250 | F23: =E23*0.1 -> 697925 | G23: =SUM(E23:F23) -> 7677175 | I23: 합계 금액 | N23: =SUM(N5:N22) -> 275858 | P23: =도착보장!AN2 -> 도착_PCM | Q23: =도착보장!AN36 -> 44051 | R23: 250 | S23: =Q23*R23 -> 11012750 | T23: =S23*0.1 -> 1101275 | U23: =SUM(S23:T23) -> 12114025
B24: =일반!AN2 -> PCM | C24: =일반!AN36 -> 81352 | D24: 250 | E24: =C24*D24 -> 20338000 | F24: =E24*0.1 -> 2033800 | G24: =SUM(E24:F24) -> 22371800 | P24: =도착보장!AP2 -> 도착_에어캡 | Q24: =도착보장!AP36 -> 865 | R24: 60 | S24: =Q24*R24 -> 51900 | T24: =S24*0.1 -> 5190 | U24: =SUM(S24:T24) -> 57090
B25: =일반!AO2 -> 드라이아이스 | C25: =일반!AO36 -> 0 | D25: 480 | E25: =C25*D25 -> 0 | F25: =E25*0.1 -> 0 | G25: =SUM(E25:F25) -> 0 | P25: =도착보장!AQ2 -> 도착_인쇄물 작업 | Q25: =도착보장!AQ36 -> 0 | R25: 100 | S25: =Q25*R25 -> 0 | T25: =S25*0.1 -> 0 | U25: =SUM(S25:T25) -> 0
B26: 폼텍라벨/제작비용 | C26: =일반!AR36 -> 0 | D26: 100 | E26: =C26*D26 -> 0 | F26: =E26*0.1 -> 0 | G26: =SUM(E26:F26) -> 0 | P26: 도착_폼텍라벨/제작비용 | R26: 100 | S26: =Q26*R26 -> 0 | T26: =S26*0.1 -> 0 | U26: =SUM(S26:T26) -> 0
B27: =일반!AP2 -> 에어캡 | C27: =일반!AP36 -> 1104 | D27: 60 | E27: =C27*D27 -> 66240 | F27: =E27*0.1 -> 6624 | G27: =SUM(E27:F27) -> 72864 | I27: 요 약 (쿠팡) | P27: =도착보장!AR2 -> 도착_신선테이핑 작업 | Q27: =도착보장!AR36 -> 0 | R27: 150 | S27: =Q27*R27 -> 0 | T27: =S27*0.1 -> 0 | U27: =SUM(S27:T27) -> 0
B28: =일반!AQ2 -> 인쇄물 작업 | C28: =일반!AQ36 -> 27 | D28: 100 | E28: =C28*D28 -> 2700 | F28: =E28*0.1 -> 270 | G28: =SUM(E28:F28) -> 2970 | N28: [ VAT 포함 ] | P28: =도착보장!AT2 -> 도착_작업료_골라담기 | Q28: =도착보장!AT36 -> 8294 | R28: 900 | S28: =Q28*R28 -> 7464600 | T28: =S28*0.1 -> 746460 | U28: =SUM(S28:T28) -> 8211060
B29: =일반!AS2 -> 신선테이핑 작업 | C29: =일반!AS36 -> 42 | D29: 150 | E29: =C29*D29 -> 6300 | F29: =E29*0.1 -> 630 | G29: =SUM(E29:F29) -> 6930 | I29: 품명 | J29: 수량 | K29: 단가 | L29: 공급가액 | M29: 세액 | N29: 합계액 | P29: =도착보장!AU2 -> 도착_작업료_세트/홈쇼핑 | Q29: =도착보장!AU36 -> 12582 | R29: 450 | S29: =Q29*R29 -> 5661900 | T29: =S29*0.1 -> 566190 | U29: =SUM(S29:T29) -> 6228090
B30: =일반!AU$2 -> 작업료_골라담기 | C30: =일반!AU36 -> 12473 | D30: 900 | E30: =C30*D30 -> 11225700 | F30: =E30*0.1 -> 1122570 | G30: =SUM(E30:F30) -> 12348270 | I30: =쿠팡택배!N2 -> 작업료_송장부착 | J30: =쿠팡택배!N35 -> 523 | K30: 600 | L30: =J30*K30 -> 313800 | M30: =L30*0.1 -> 31380 | N30: =SUM(L30:M30) -> 345180 | P30: =도착보장!AV2 -> 도착_부직포세트 | Q30: =도착보장!AV36 -> 0 | R30: 700 | S30: =Q30*R30 -> 0 | T30: =S30*0.1 -> 0 | U30: =SUM(S30:T30) -> 0
B31: =일반!AV$2 -> 작업료_세트/홈쇼핑 | C31: =일반!AV36 -> 25382 | D31: 450 | E31: =C31*D31 -> 11421900 | F31: =E31*0.1 -> 1142190 | G31: =SUM(E31:F31) -> 12564090 | I31: =쿠팡택배!O2 -> 작업료_스티커 부착 | J31: =쿠팡택배!O35 -> 2091 | K31: 100 | L31: =J31*K31 -> 209100 | M31: =L31*0.1 -> 20910 | N31: =SUM(L31:M31) -> 230010 | P31: =도착보장!AW2 -> 도착_작업료_송장부착 | Q31: =도착보장!AW36 -> 358 | R31: 600 | S31: =Q31*R31 -> 214800 | T31: =S31*0.1 -> 21480 | U31: =SUM(S31:T31) -> 236280
B32: =일반!AW2 -> 작업료_부직포세트 | C32: =일반!AW36 -> 12 | D32: 700 | E32: =C32*D32 -> 8400 | F32: =E32*0.1 -> 840 | G32: =SUM(E32:F32) -> 9240 | I32: =쿠팡택배!Q2 -> 상온_택배비_극소 | J32: =쿠팡택배!Q35 -> 0 | K32: 1800 | L32: =J32*K32 -> 0 | M32: =L32*0.1 -> 0 | N32: =SUM(L32:M32) -> 0 | P32: =도착보장!BA2 -> 도착_저온_택배비_극소 | Q32: =도착보장!BA36 -> 13582 | R32: =D36+155 -> 2205 | S32: =Q32*R32 -> 29948310 | T32: =S32*0.1 -> 2994831 | U32: =SUM(S32:T32) -> 32943141
B33: =일반!AX2 -> 작업료_송장부착 | C33: =일반!AX36 -> 1154 | D33: 600 | E33: =C33*D33 -> 692400 | F33: =E33*0.1 -> 69240 | G33: =SUM(E33:F33) -> 761640 | I33: =쿠팡택배!R2 -> 상온_택배비_소 | J33: =쿠팡택배!R35 -> 83 | K33: 2200 | L33: =J33*K33 -> 182600 | M33: =L33*0.1 -> 18260 | N33: =SUM(L33:M33) -> 200860 | P33: =도착보장!BB2 -> 도착_저온_택배비_소 | Q33: =도착보장!BB36 -> 3902 | R33: =D37+155 -> 2705 | S33: =Q33*R33 -> 10554910 | T33: =S33*0.1 -> 1055491 | U33: =SUM(S33:T33) -> 11610401
B34: =일반!AY2 -> 작업료_조립폴리 | C34: =일반!AY36 -> 0 | D34: 950 | E34: =C34*D34 -> 0 | F34: =E34*0.1 -> 0 | G34: =SUM(E34:F34) -> 0 | I34: =쿠팡택배!S2 -> 상온_택배비_중 | J34: =쿠팡택배!S35 -> 440 | K34: 2700 | L34: =J34*K34 -> 1188000 | M34: =L34*0.1 -> 118800 | N34: =SUM(L34:M34) -> 1306800 | P34: =도착보장!BC2 -> 도착_저온_택배비_중 | Q34: =도착보장!BC36 -> 714 | R34: =D38+155 -> 3355 | S34: =Q34*R34 -> 2395470 | T34: =S34*0.1 -> 239547 | U34: =SUM(S34:T34) -> 2635017
B35: 작업료_해체비 | C35: =일반!AZ36 -> 0 | D35: 550 | E35: =C35*D35 -> 0 | F35: =E35*0.1 -> 0 | G35: =SUM(E35:F35) -> 0 | I35: 합계 금액 | N35: =SUM(N30:N34) -> 2082850 | P35: =도착보장!BD2 -> 도착_저온_택배비_대 | Q35: =도착보장!BD36 -> 55 | R35: =D39+155 -> 4905 | S35: =Q35*R35 -> 269775 | T35: =S35*0.1 -> 26977.5 | U35: =SUM(S35:T35) -> 296752.5
B36: =일반!BB$2 -> 저온_택배비_극소 | C36: =일반!BB36 -> 19378 | D36: 2050 | E36: =C36*D36 -> 39724900 | F36: =E36*0.1 -> 3972490 | G36: =SUM(E36:F36) -> 43697390 | P36: =도착보장!BG2 -> 도착_상온_택배비_극소 | Q36: =도착보장!BG36 -> 2575 | R36: =D42+155 -> 1955 | S36: =Q36*R36 -> 5034125 | T36: =S36*0.1 -> 503412.5 | U36: =SUM(S36:T36) -> 5537537.5
B37: =일반!BC$2 -> 저온_택배비_소 | C37: =일반!BC36 -> 12537 | D37: 2550 | E37: =C37*D37 -> 31969350 | F37: =E37*0.1 -> 3196935 | G37: =SUM(E37:F37) -> 35166285 | P37: =도착보장!BH2 -> 도착_상온_택배비_소 | Q37: =도착보장!BH36 -> 48 | R37: =D43+155 -> 2355 | S37: =Q37*R37 -> 113040 | T37: =S37*0.1 -> 11304 | U37: =SUM(S37:T37) -> 124344
B38: =일반!BD$2 -> 저온_택배비_중 | C38: =일반!BD36 -> 1213 | D38: 3200 | E38: =C38*D38 -> 3881600 | F38: =E38*0.1 -> 388160 | G38: =SUM(E38:F38) -> 4269760 | P38: =도착보장!BI2 -> 도착_상온_택배비_중 | Q38: =도착보장!BI36 -> 358 | R38: =D44+155 -> 2855 | S38: =Q38*R38 -> 1022090 | T38: =S38*0.1 -> 102209 | U38: =SUM(S38:T38) -> 1124299
B39: =일반!BE$2 -> 저온_택배비_대 | C39: =일반!BE36 -> 183 | D39: 4750 | E39: =C39*D39 -> 869250 | F39: =E39*0.1 -> 86925 | G39: =SUM(E39:F39) -> 956175 | P39: =도착보장!BJ2 -> 도착_상온_택배비_대 | Q39: =도착보장!BJ36 -> 0 | R39: =D45+155 -> 4455 | S39: =Q39*R39 -> 0 | T39: =S39*0.1 -> 0 | U39: =SUM(S39:T39) -> 0
B40: =일반!BF$2 -> 저온_택배비_대2 | C40: =일반!BF36 -> 0 | D40: 4860 | E40: =C40*D40 -> 0 | F40: =E40*0.1 -> 0 | G40: =SUM(E40:F40) -> 0 | P40: 합계 금액 | U40: =SUM(U5:U39) -> 97887328
B41: =일반!BG$2 -> 저온_택배비_이형1 | C41: =일반!BG36 -> 0 | D41: 12320 | E41: =C41*D41 -> 0 | F41: =E41*0.1 -> 0 | G41: =SUM(E41:F41) -> 0
...

Sheet 일반
B1: 일반
A2: ㈜농협목우촌 | B2: 일반_아이스박스_2K | C2: 일반_아이스박스_1호 | D2: 일반_아이스박스_T135 | E2: 일반_아이스박스_2호 | F2: 일반_아이스박스_3호 | G2: 일반_아이스박스_4호 | H2: 일반_아이스박스_5호 | I2: 일반_아이스박스_6호 | J2: 일반_아이스박스_7호 | K2: 일반_아이스박스_1호 | L2: 일반_아이스박스_T135 | M2: 일반_아이스박스_2호 | N2: 일반_아이스박스_3호 | O2: 일반_아이스박스_4호 | P2: 일반_아이스박스_5호 | Q2: 일반_아이스박스_6호 | R2: 일반_아이스박스_7호 | S2: 냉동_송장부착 | T2: 일반_종이박스_1호 | U2: 일반_종이박스_2호 | V2: 일반_종이박스_2호 (강) | W2: 일반_종이박스_3호 | X2: 일반_종이박스_4호 | Y2: 일반_종이박스_5호 | Z2: 송장부착 | AA2: 보냉세트 (1개) | AB2: 보냉세트 (2개) | AC2: 보냉 6호 | AD2: 보냉 7호 | AE2: 폴리세트 (1개) | AF2: 폴리세트 (2개) | AG2: 조립폴리세트 | AH2: 부직포세트 | AI2: 송장부착세트 | AJ2: 총수량 | AL2: 아이스팩_500g | AM2: 아이스팩_1000g | AN2: PCM | AO2: 드라이아이스 | AP2: 에어캡 | AQ2: 인쇄물 작업 | AR2: 폼텍라벨/ 제작비용 | AS2: 신선테이핑 작업 | AU2: 작업료_골라담기 | AV2: 작업료_세트/홈쇼핑 | AW2: 작업료_부직포세트 | AX2: 작업료_송장부착 | AY2: 작업료_조립폴리 | AZ2: 작업료_해체비 | BB2: 저온_택배비_극소 | BC2: 저온_택배비_소 | BD2: 저온_택배비_중 | BE2: 저온_택배비_대 | BF2: 저온_택배비_대2 | BG2: 저온_택배비_이형1 | BH2: 상온_택배비_극소 | BI2: 상온_택배비_소 | BJ2: 상온_택배비_중 | BK2: 상온_택배비_대 | BM2: 입고비_Pallet | BN2: 입고비_BOX | BO2: 특이사항
A3: 사이즈 | B3: 극소 | C3: 극소 | D3: 극소 | E3: 소 | F3: 소 | G3: 중 | H3: 중 | I3: 대 | J3: 대 | K3: 극소 | L3: 극소 | M3: 소 | N3: 소 | O3: 중 | P3: 중 | Q3: 대 | R3: 대 | S3: 소 | T3: 극소 | U3: 극소 | V3: 극소 | W3: 소 | X3: 중 | Y3: 대 | Z3: 중 | AA3: 보냉팩 | AB3: 보냉팩 | AC3: 대 | AD3: 대 | AE3: 폴리백 | AF3: 폴리백 | AG3: 폴리백 | AH3: 부직포 | AI3: 중 | BB3: 극소 | BC3: 소 | BD3: 중 | BE3: 대 | BF3: 대2 | BG3: 이형 | BH3: 극소 | BI3: 소 | BJ3: 중 | BK3: 대
A4: 품온 | B4: 냉장 | K4: 냉동 | T4: 상온 | AA4: 세트
A5: 46235 | AJ5: =SUM(B5:AI5) -> 0 | AL5: =B5+SUM(C5:D5)*2+SUM(I5:J5)+SUM(K5:L5)*2+SUM(M5:N5)*3+AH5+SUM(AA5:AD5) -> 0 | AM5: =SUM(E5:J5)+SUM(O5:R5)*3 -> 0 | AN5: =B5+SUM(C5:D5)*2+SUM(K5:N5)*2+SUM(O5:R5) -> 0 | AO5: 0 | AQ5: 0 | AS5: =SUM(AA5:AB5)+AH5+S5 -> 0 | AU5: =AJ5-AV5-AW5-AX5 -> 0 | AV5: 0 | AW5: =AH5 -> 0 | AX5: =Z5+S5+AI5 -> 0 | AY5: =AG5 -> 0 | AZ5: 0 | BB5: =SUM(B5:D5)+K5+L5+AA5 -> 0 | BC5: =SUM(E5:F5)+SUM(M5:N5)+AB5+AH5+S5 -> 0 | BD5: =SUM(G5:H5)+O5+P5 -> 0 | BE5: =SUM(I5:J5)+Q5+R5+AC5+AD5 -> 0 | BH5: =SUM(T5:V5)+AE5+AG5 -> 0 | BI5: =W5+AF5 -> 0 | BJ5: =X5+Z5+AI5 -> 0 | BK5: =Y5 -> 0
A6: =A5+1 -> 46236 | AJ6: =SUM(B6:AI6) -> 0 | AL6: =B6+SUM(C6:D6)*2+SUM(I6:J6)+SUM(K6:L6)*2+SUM(M6:N6)*3+AH6+SUM(AA6:AD6) -> 0 | AM6: =SUM(E6:J6)+SUM(O6:R6)*3 -> 0 | AN6: =B6+SUM(C6:D6)*2+SUM(K6:N6)*2+SUM(O6:R6) -> 0 | AO6: 0 | AQ6: 0 | AS6: =SUM(AA6:AB6)+AH6+S6 -> 0 | AU6: =AJ6-AV6-AW6-AX6 -> 0 | AV6: 0 | AW6: =AH6 -> 0 | AX6: =Z6+S6+AI6 -> 0 | AY6: =AG6 -> 0 | AZ6: 0 | BB6: =SUM(B6:D6)+K6+L6+AA6 -> 0 | BC6: =SUM(E6:F6)+SUM(M6:N6)+AB6+AH6+S6 -> 0 | BD6: =SUM(G6:H6)+O6+P6 -> 0 | BE6: =SUM(I6:J6)+Q6+R6+AC6+AD6 -> 0 | BH6: =SUM(T6:V6)+AE6+AG6 -> 0 | BI6: =W6+AF6 -> 0 | BJ6: =X6+Z6+AI6 -> 0 | BK6: =Y6 -> 0
A7: =A6+1 -> 46237 | B7: 0 | C7: 875 | D7: 203 | E7: 21 | F7: 20 | G7: 12 | H7: 2 | I7: 0 | J7: 0 | K7: 17 | L7: 22 | M7: 97 | N7: 80 | O7: 17 | P7: 23 | Q7: 5 | R7: 1 | T7: 38 | U7: 28 | V7: 0 | W7: 7 | X7: 1 | Y7: 0 | Z7: 26 | AA7: 0 | AB7: 0 | AC7: 0 | AD7: 0 | AE7: 1 | AF7: 0 | AG7: 0 | AH7: 2 | AI7: 0 | AJ7: =SUM(B7:AI7) -> 1498 | AL7: =B7+SUM(C7:D7)*2+SUM(I7:J7)+SUM(K7:L7)*2+SUM(M7:N7)*3+AH7+SUM(AA7:AD7) -> 2767 | AM7: =SUM(E7:J7)+SUM(O7:R7)*3 -> 193 | AN7: =B7+SUM(C7:D7)*2+SUM(K7:N7)*2+SUM(O7:R7) -> 2634 | AO7: 0 | AP7: 79 | AQ7: 0 | AS7: =SUM(AA7:AB7)+AH7+S7 -> 2 | AU7: =AJ7-AV7-AW7-AX7 -> 684 | AV7: 786 | AW7: =AH7 -> 2 | AX7: =Z7+S7+AI7 -> 26 | AY7: =AG7 -> 0 | AZ7: 0 | BB7: =SUM(B7:D7)+K7+L7+AA7 -> 1117 | BC7: =SUM(E7:F7)+SUM(M7:N7)+AB7+AH7+S7 -> 220 | BD7: =SUM(G7:H7)+O7+P7 -> 54 | BE7: =SUM(I7:J7)+Q7+R7+AC7+AD7 -> 6 | BH7: =SUM(T7:V7)+AE7+AG7 -> 67 | BI7: =W7+AF7 -> 7 | BJ7: =X7+Z7+AI7 -> 27 | BK7: =Y7 -> 0 | BM7: 28
A8: =A7+1 -> 46238 | B8: 0 | C8: 230 | D8: 106 | E8: 19 | F8: 25 | G8: 15 | H8: 0 | I8: 0 | J8: 0 | K8: 5 | L8: 8 | M8: 43 | N8: 38 | O8: 10 | P8: 9 | Q8: 3 | R8: 8 | T8: 9 | U8: 7 | V8: 0 | W8: 4 | X8: 0 | Y8: 0 | Z8: 4 | AA8: 0 | AB8: 0 | AC8: 0 | AD8: 0 | AE8: 0 | AF8: 0 | AG8: 0 | AH8: 0 | AI8: 0 | AJ8: =SUM(B8:AI8) -> 543 | AL8: =B8+SUM(C8:D8)*2+SUM(I8:J8)+SUM(K8:L8)*2+SUM(M8:N8)*3+AH8+SUM(AA8:AD8) -> 941 | AM8: =SUM(E8:J8)+SUM(O8:R8)*3 -> 149 | AN8: =B8+SUM(C8:D8)*2+SUM(K8:N8)*2+SUM(O8:R8) -> 890 | AO8: 0 | AP8: 34 | AQ8: 0 | AS8: =SUM(AA8:AB8)+AH8+S8 -> 0 | AU8: =AJ8-AV8-AW8-AX8 -> 492 | AV8: 47 | AW8: =AH8 -> 0 | AX8: =Z8+S8+AI8 -> 4 | AY8: =AG8 -> 0 | AZ8: 0 | BB8: =SUM(B8:D8)+K8+L8+AA8 -> 349 | BC8: =SUM(E8:F8)+SUM(M8:N8)+AB8+AH8+S8 -> 125 | BD8: =SUM(G8:H8)+O8+P8 -> 34 | BE8: =SUM(I8:J8)+Q8+R8+AC8+AD8 -> 11 | BH8: =SUM(T8:V8)+AE8+AG8 -> 16 | BI8: =W8+AF8 -> 4 | BJ8: =X8+Z8+AI8 -> 4 | BK8: =Y8 -> 0 | BM8: 22
A9: =A8+1 -> 46239 | B9: 0 | C9: 271 | D9: 100 | E9: 26 | F9: 21 | G9: 4 | H9: 2 | I9: 0 | J9: 0 | K9: 0 | L9: 36 | M9: 58 | N9: 50 | O9: 14 | P9: 18 | Q9: 2 | R9: 4 | T9: 9 | U9: 9 | V9: 0 | W9: 2 | X9: 0 | Y9: 0 | Z9: 6 | AA9: 0 | AB9: 0 | AC9: 0 | AD9: 0 | AE9: 2 | AF9: 0 | AG9: 0 | AH9: 1 | AI9: 0 | AJ9: =SUM(B9:AI9) -> 635 | AL9: =B9+SUM(C9:D9)*2+SUM(I9:J9)+SUM(K9:L9)*2+SUM(M9:N9)*3+AH9+SUM(AA9:AD9) -> 1139 | AM9: =SUM(E9:J9)+SUM(O9:R9)*3 -> 167 | AN9: =B9+SUM(C9:D9)*2+SUM(K9:N9)*2+SUM(O9:R9) -> 1068 | AO9: 0 | AP9: 25 | AQ9: 0 | AS9: =SUM(AA9:AB9)+AH9+S9 -> 1 | AU9: =AJ9-AV9-AW9-AX9 -> 560 | AV9: 68 | AW9: =AH9 -> 1 | AX9: =Z9+S9+AI9 -> 6 | AY9: =AG9 -> 0 | AZ9: 0 | BB9: =SUM(B9:D9)+K9+L9+AA9 -> 407 | BC9: =SUM(E9:F9)+SUM(M9:N9)+AB9+AH9+S9 -> 156 | BD9: =SUM(G9:H9)+O9+P9 -> 38 | BE9: =SUM(I9:J9)+Q9+R9+AC9+AD9 -> 6 | BH9: =SUM(T9:V9)+AE9+AG9 -> 20 | BI9: =W9+AF9 -> 2 | BJ9: =X9+Z9+AI9 -> 6 | BK9: =Y9 -> 0 | BM9: 41
A10: =A9+1 -> 46240 | B10: 0 | C10: 1079 | D10: 167 | E10: 72 | F10: 1027 | G10: 18 | H10: 3 | I10: 0 | J10: 0 | K10: 37 | L10: 32 | M10: 68 | N10: 79 | O10: 36 | P10: 18 | Q10: 7 | R10: 6 | T10: 30 | U10: 16 | V10: 0 | W10: 20 | X10: 1 | Y10: 0 | Z10: 23 | AA10: 0 | AB10: 0 | AC10: 0 | AD10: 0 | AE10: 1 | AF10: 0 | AG10: 0 | AI10: 0 | AJ10: =SUM(B10:AI10) -> 2740 | AL10: =B10+SUM(C10:D10)*2+SUM(I10:J10)+SUM(K10:L10)*2+SUM(M10:N10)*3+AH10+SUM(AA10:AD10) -> 3071 | AM10: =SUM(E10:J10)+SUM(O10:R10)*3-1000+1000*3 -> 3321 | AN10: =B10+SUM(C10:D10)*2+SUM(K10:N10)*2+SUM(O10:R10)+1000*3 -> 5991 | AO10: 0 | AP10: 54 | AQ10: 0 | AS10: =SUM(AA10:AB10)+AH10+S10 -> 0 | AU10: =AJ10-AV10-AW10-AX10 -> 815 | AV10: 1902 | AW10: =AH10 -> 0 | AX10: =Z10+S10+AI10 -> 23 | AY10: =AG10 -> 0 | AZ10: 0 | BB10: =SUM(B10:D10)+K10+L10+AA10 -> 1315 | BC10: =SUM(E10:F10)+SUM(M10:N10)+AB10+AH10+S10 -> 1246 | BD10: =SUM(G10:H10)+O10+P10 -> 75 | BE10: =SUM(I10:J10)+Q10+R10+AC10+AD10 -> 13 | BH10: =SUM(T10:V10)+AE10+AG10 -> 47 | BI10: =W10+AF10 -> 20 | BJ10: =X10+Z10+AI10 -> 24 | BK10: =Y10 -> 0 | BM10: 34 | BN10: 7
A11: =A10+1 -> 46241 | B11: 0 | C11: 1173 | D11: 139 | E11: 50 | F11: 1029 | G11: 14 | H11: 3 | I11: 0 | J11: 0 | K11: 23 | L11: 20 | M11: 27 | N11: 61 | O11: 20 | P11: 14 | Q11: 4 | R11: 3 | T11: 24 | U11: 11 | V11: 0 | W11: 6 | X11: 0 | Y11: 0 | Z11: 2 | AA11: 0 | AB11: 0 | AC11: 0 | AD11: 0 | AE11: 0 | AF11: 0 | AG11: 0 | AH11: 0 | AI11: 0 | AJ11: =SUM(B11:AI11) -> 2623 | AL11: =B11+SUM(C11:D11)*2+SUM(I11:J11)+SUM(K11:L11)*2+SUM(M11:N11)*3+AH11+SUM(AA11:AD11) -> 2974 | AM11: =SUM(E11:J11)+SUM(O11:R11)*3-1000+1000*3 -> 3219 | AN11: =B11+SUM(C11:D11)*2+SUM(K11:N11)*2+SUM(O11:R11)+1000*3 -> 5927 | AO11: 0 | AP11: 33 | AQ11: 0 | AS11: =SUM(AA11:AB11)+AH11+S11 -> 0 | AU11: =AJ11-AV11-AW11-AX11 -> 623 | AV11: 1998 | AW11: =AH11 -> 0 | AX11: =Z11+S11+AI11 -> 2 | AY11: =AG11 -> 0 | AZ11: 0 | BB11: =SUM(B11:D11)+K11+L11+AA11 -> 1355 | BC11: =SUM(E11:F11)+SUM(M11:N11)+AB11+AH11+S11 -> 1167 | BD11: =SUM(G11:H11)+O11+P11 -> 51 | BE11: =SUM(I11:J11)+Q11+R11+AC11+AD11 -> 7 | BH11: =SUM(T11:V11)+AE11+AG11 -> 35 | BI11: =W11+AF11 -> 6 | BJ11: =X11+Z11+AI11 -> 2 | BK11: =Y11 -> 0 | BM11: 20
A12: =A11+1 -> 46242 | AJ12: =SUM(B12:AI12) -> 0 | AL12: =B12+SUM(C12:D12)*2+SUM(I12:J12)+SUM(K12:L12)*2+SUM(M12:N12)*3+AH12+SUM(AA12:AD12) -> 0 | AM12: =SUM(E12:J12)+SUM(O12:R12)*3 -> 0 | AN12: =B12+SUM(C12:D12)*2+SUM(K12:N12)*2+SUM(O12:R12) -> 0 | AO12: 0 | AQ12: 0 | AS12: =SUM(AA12:AB12)+AH12+S12 -> 0 | AU12: =AJ12-AV12-AW12-AX12 -> 0 | AV12: 0 | AW12: =AH12 -> 0 | AX12: =Z12+S12+AI12 -> 0 | AY12: =AG12 -> 0 | AZ12: 0 | BB12: =SUM(B12:D12)+K12+L12+AA12 -> 0 | BC12: =SUM(E12:F12)+SUM(M12:N12)+AB12+AH12+S12 -> 0 | BD12: =SUM(G12:H12)+O12+P12 -> 0 | BE12: =SUM(I12:J12)+Q12+R12+AC12+AD12 -> 0 | BH12: =SUM(T12:V12)+AE12+AG12 -> 0 | BI12: =W12+AF12 -> 0 | BJ12: =X12+Z12+AI12 -> 0 | BK12: =Y12 -> 0
A13: =A12+1 -> 46243 | AJ13: =SUM(B13:AI13) -> 0 | AL13: =B13+SUM(C13:D13)*2+SUM(I13:J13)+SUM(K13:L13)*2+SUM(M13:N13)*3+AH13+SUM(AA13:AD13) -> 0 | AM13: =SUM(E13:J13)+SUM(O13:R13)*3 -> 0 | AN13: =B13+SUM(C13:D13)*2+SUM(K13:N13)*2+SUM(O13:R13) -> 0 | AO13: 0 | AQ13: 0 | AS13: =SUM(AA13:AB13)+AH13+S13 -> 0 | AU13: =AJ13-AV13-AW13-AX13 -> 0 | AV13: 0 | AW13: =AH13 -> 0 | AX13: =Z13+S13+AI13 -> 0 | AY13: =AG13 -> 0 | AZ13: 0 | BB13: =SUM(B13:D13)+K13+L13+AA13 -> 0 | BC13: =SUM(E13:F13)+SUM(M13:N13)+AB13+AH13+S13 -> 0 | BD13: =SUM(G13:H13)+O13+P13 -> 0 | BE13: =SUM(I13:J13)+Q13+R13+AC13+AD13 -> 0 | BH13: =SUM(T13:V13)+AE13+AG13 -> 0 | BI13: =W13+AF13 -> 0 | BJ13: =X13+Z13+AI13 -> 0 | BK13: =Y13 -> 0
A14: =A13+1 -> 46244 | B14: 0 | C14: 582 | D14: 153 | E14: 17 | F14: 1006 | G14: 31 | H14: 3 | I14: 0 | J14: 0 | K14: 0 | L14: 5 | M14: 6 | N14: 29 | O14: 2 | P14: 1 | Q14: 1 | R14: 0 | T14: 2638 | U14: 37 | V14: 0 | W14: 0 | X14: 0 | Y14: 0 | Z14: 202 | AJ14: =SUM(B14:AI14) -> 4713 | AL14: =B14+SUM(C14:D14)*2+SUM(I14:J14)+SUM(K14:L14)*2+SUM(M14:N14)*3+AH14+SUM(AA14:AD14)+30 -> 1615 | AM14: =SUM(E14:J14)+SUM(O14:R14)*3-1000+1000*3 -> 3069 | AN14: =B14+SUM(C14:D14)*2+SUM(K14:N14)*2+SUM(O14:R14)+1000*3 -> 4554 | AO14: 0 | AP14: 20 | AQ14: 27 | AS14: =SUM(AA14:AB14)+AH14+S14 -> 0 | AU14: =AJ14-AV14-AW14-AX14 -> 115 | AV14: 4396 | AW14: =AH14 -> 0 | AX14: =Z14+S14+AI14 -> 202 | AY14: =AG14 -> 0 | AZ14: 0 | BB14: =SUM(B14:D14)+K14+L14+AA14 -> 740 | BC14: =SUM(E14:F14)+SUM(M14:N14)+AB14+AH14+S14 -> 1058 | BD14: =SUM(G14:H14)+O14+P14 -> 37 | BE14: =SUM(I14:J14)+Q14+R14+AC14+AD14 -> 1 | BH14: =SUM(T14:V14)+AE14+AG14 -> 2675 | BI14: =W14+AF14 -> 0 | BJ14: =X14+Z14+AI14 -> 202 | BK14: =Y14 -> 0 | BM14: 17
A15: =A14+1 -> 46245 | B15: 0 | C15: 640 | D15: 249 | E15: 49 | F15: 1006 | G15: 50 | H15: 2 | I15: 0 | J15: 0 | K15: 449 | L15: 76 | M15: 444 | N15: 214 | O15: 122 | P15: 37 | Q15: 13 | R15: 1 | T15: 181 | U15: 42 | V15: 0 | W15: 17 | X15: 0 | Y15: 0 | Z15: 205 | AE15: 4 | AH15: 1 | AJ15: =SUM(B15:AI15) -> 3802 | AL15: =B15+SUM(C15:D15)*2+SUM(I15:J15)+SUM(K15:L15)*2+SUM(M15:N15)*3+AH15+SUM(AA15:AD15)+23+327 -> 5153 | AM15: =SUM(E15:J15)+SUM(O15:R15)*3-993+993*3 -> 3612 | AN15: =B15+SUM(C15:D15)*2+SUM(K15:N15)*2+SUM(O15:R15)+993*3-654 -> 6642 | AO15: 0 | AP15: 175 | AQ15: 0 | AS15: =SUM(AA15:AB15)+AH15+S15 -> 1 | AU15: =AJ15-AV15-AW15-AX15 -> 1130 | AV15: 2466 | AW15: =AH15 -> 1 | AX15: =Z15+S15+AI15 -> 205 | AY15: =AG15 -> 0 | AZ15: 0 | BB15: =SUM(B15:D15)+K15+L15+AA15 -> 1414 | BC15: =SUM(E15:F15)+SUM(M15:N15)+AB15+AH15+S15 -> 1714 | BD15: =SUM(G15:H15)+O15+P15 -> 211 | BE15: =SUM(I15:J15)+Q15+R15+AC15+AD15 -> 14 | BH15: =SUM(T15:V15)+AE15+AG15 -> 227 | BI15: =W15+AF15 -> 17 | BJ15: =X15+Z15+AI15 -> 205 | BK15: =Y15 -> 0 | BM15: 13
A16: =A15+1 -> 46246 | B16: 0 | C16: 622 | D16: 134 | E16: 7 | F16: 1020 | G16: 9 | H16: 4 | I16: 0 | J16: 0 | K16: 744 | L16: 21 | M16: 400 | N16: 195 | O16: 86 | P16: 20 | Q16: 4 | R16: 6 | T16: 14 | U16: 9 | V16: 0 | W16: 7 | X16: 0 | Y16: 0 | Z16: 4 | AA16: 0 | AB16: 0 | AC16: 0 | AD16: 0 | AE16: 0 | AF16: 0 | AG16: 0 | AH16: 0 | AI16: 0 | AJ16: =SUM(B16:AI16) -> 3306 | AL16: =SUM(K16:L16)*2+SUM(M16:N16)*3+AH16+SUM(AA16:AD16)+693 -> 4008 | AM16: =SUM(E16:J16)+SUM(O16:R16)*3-1000+1000*3 -> 3388 | AN16: =SUM(C16:D16)*3+SUM(E16:H16)*2+SUM(I16:J16)*3+SUM(K16:N16)*2+SUM(O16:R16)+1000-1386 -> 6798 | AO16: 0 | AP16: 37 | AQ16: 0 | AS16: =SUM(AA16:AB16)+AH16+S16 -> 0 | AU16: =AJ16-AV16-AW16-AX16 -> 669 | AV16: 2633 | AW16: =AH16 -> 0 | AX16: =Z16+S16+AI16 -> 4 | AY16: =AG16 -> 0 | AZ16: 0 | BB16: =SUM(B16:D16)+K16+L16+AA16 -> 1521 | BC16: =SUM(E16:F16)+SUM(M16:N16)+AB16+AH16+S16 -> 1622 | BD16: =SUM(G16:H16)+O16+P16 -> 119 | BE16: =SUM(I16:J16)+Q16+R16+AC16+AD16 -> 10 | BH16: =SUM(T16:V16)+AE16+AG16 -> 23 | BI16: =W16+AF16 -> 7 | BJ16: =X16+Z16+AI16 -> 4 | BK16: =Y16 -> 0 | BM16: 19
A17: =A16+1 -> 46247 | AJ17: =SUM(B17:AI17) -> 0 | AL17: =SUM(K17:L17)*2+SUM(M17:N17)*3+AH17+SUM(AA17:AD17) -> 0 | AM17: =SUM(E17:J17)+SUM(O17:R17)*3 -> 0 | AN17: =SUM(C17:D17)*3+SUM(E17:H17)*2+SUM(I17:J17)*3+SUM(K17:N17)*2+SUM(O17:R17) -> 0 | AO17: 0 | AQ17: 0 | AS17: =SUM(AA17:AB17)+AH17+S17 -> 0 | AU17: =AJ17-AV17-AW17-AX17 -> 0 | AV17: 0 | AW17: =AH17 -> 0 | AX17: =Z17+S17+AI17 -> 0 | AY17: =AG17 -> 0 | AZ17: 0 | BB17: =SUM(B17:D17)+K17+L17+AA17 -> 0 | BC17: =SUM(E17:F17)+SUM(M17:N17)+AB17+AH17+S17 -> 0 | BD17: =SUM(G17:H17)+O17+P17 -> 0 | BE17: =SUM(I17:J17)+Q17+R17+AC17+AD17 -> 0 | BH17: =SUM(T17:V17)+AE17+AG17 -> 0 | BI17: =W17+AF17 -> 0 | BJ17: =X17+Z17+AI17 -> 0 | BK17: =Y17 -> 0 | BM17: 16
A18: =A17+1 -> 46248 | AJ18: =SUM(B18:AI18) -> 0 | AL18: =SUM(K18:L18)*2+SUM(M18:N18)*3+AH18+SUM(AA18:AD18) -> 0 | AM18: =SUM(E18:J18)+SUM(O18:R18)*3 -> 0 | AN18: =SUM(C18:D18)*3+SUM(E18:H18)*2+SUM(I18:J18)*3+SUM(K18:N18)*2+SUM(O18:R18) -> 0 | AO18: 0 | AQ18: 0 | AS18: =SUM(AA18:AB18)+AH18+S18 -> 0 | AU18: =AJ18-AV18-AW18-AX18 -> 0 | AV18: 0 | AW18: =AH18 -> 0 | AX18: =Z18+S18+AI18 -> 0 | AY18: =AG18 -> 0 | AZ18: 0 | BB18: =SUM(B18:D18)+K18+L18+AA18 -> 0 | BC18: =SUM(E18:F18)+SUM(M18:N18)+AB18+AH18+S18 -> 0 | BD18: =SUM(G18:H18)+O18+P18 -> 0 | BE18: =SUM(I18:J18)+Q18+R18+AC18+AD18 -> 0 | BH18: =SUM(T18:V18)+AE18+AG18 -> 0 | BI18: =W18+AF18 -> 0 | BJ18: =X18+Z18+AI18 -> 0 | BK18: =Y18 -> 0 | BM18: 28
A19: =A18+1 -> 46249 | AJ19: =SUM(B19:AI19) -> 0 | AL19: =SUM(K19:L19)*2+SUM(M19:N19)*3+AH19+SUM(AA19:AD19) -> 0 | AM19: =SUM(E19:J19)+SUM(O19:R19)*3 -> 0 | AN19: =SUM(C19:D19)*3+SUM(E19:H19)*2+SUM(I19:J19)*3+SUM(K19:N19)*2+SUM(O19:R19) -> 0 | AO19: 0 | AQ19: 0 | AS19: =SUM(AA19:AB19)+AH19+S19 -> 0 | AU19: =AJ19-AV19-AW19-AX19 -> 0 | AV19: 0 | AW19: =AH19 -> 0 | AX19: =Z19+S19+AI19 -> 0 | AY19: =AG19 -> 0 | AZ19: 0 | BB19: =SUM(B19:D19)+K19+L19+AA19 -> 0 | BC19: =SUM(E19:F19)+SUM(M19:N19)+AB19+AH19+S19 -> 0 | BD19: =SUM(G19:H19)+O19+P19 -> 0 | BE19: =SUM(I19:J19)+Q19+R19+AC19+AD19 -> 0 | BH19: =SUM(T19:V19)+AE19+AG19 -> 0 | BI19: =W19+AF19 -> 0 | BJ19: =X19+Z19+AI19 -> 0 | BK19: =Y19 -> 0
A20: =A19+1 -> 46250 | AJ20: =SUM(B20:AI20) -> 0 | AL20: =SUM(K20:L20)*2+SUM(M20:N20)*3+AH20+SUM(AA20:AD20) -> 0 | AM20: =SUM(E20:J20)+SUM(O20:R20)*3 -> 0 | AN20: =SUM(C20:D20)*3+SUM(E20:H20)*2+SUM(I20:J20)*3+SUM(K20:N20)*2+SUM(O20:R20) -> 0 | AO20: 0 | AQ20: 0 | AS20: =SUM(AA20:AB20)+AH20+S20 -> 0 | AU20: =AJ20-AV20-AW20-AX20 -> 0 | AV20: 0 | AW20: =AH20 -> 0 | AX20: =Z20+S20+AI20 -> 0 | AY20: =AG20 -> 0 | AZ20: 0 | BB20: =SUM(B20:D20)+K20+L20+AA20 -> 0 | BC20: =SUM(E20:F20)+SUM(M20:N20)+AB20+AH20+S20 -> 0 | BD20: =SUM(G20:H20)+O20+P20 -> 0 | BE20: =SUM(I20:J20)+Q20+R20+AC20+AD20 -> 0 | BH20: =SUM(T20:V20)+AE20+AG20 -> 0 | BI20: =W20+AF20 -> 0 | BJ20: =X20+Z20+AI20 -> 0 | BK20: =Y20 -> 0
A21: =A20+1 -> 46251 | B21: 0 | C21: 1898 | D21: 716 | E21: 6 | F21: 37 | G21: 18 | H21: 5 | I21: 0 | J21: 0 | K21: 2 | L21: 5 | M21: 26 | N21: 45 | O21: 18 | P21: 29 | Q21: 11 | R21: 4 | T21: 15 | U21: 44 | V21: 0 | W21: 2 | X21: 0 | Y21: 0 | Z21: 26 | AJ21: =SUM(B21:AI21) -> 2907 | AL21: =SUM(K21:L21)*2+SUM(M21:N21)*3+AH21+SUM(AA21:AD21) -> 227 | AM21: =SUM(E21:J21)+SUM(O21:R21)*3+34 -> 286 | AN21: =SUM(C21:D21)*3+SUM(E21:H21)*2+SUM(I21:J21)*3+SUM(K21:N21)*2+SUM(O21:R21)+17 -> 8209 | AO21: 0 | AP21: 171 | AQ21: 0 | AS21: =SUM(AA21:AB21)+AH21+S21 -> 0 | AU21: =AJ21-AV21-AW21-AX21 -> 373 | AV21: 2508 | AW21: =AH21 -> 0 | AX21: =Z21+S21+AI21 -> 26 | AY21: =AG21 -> 0 | AZ21: 0 | BB21: =SUM(B21:D21)+K21+L21+AA21 -> 2621 | BC21: =SUM(E21:F21)+SUM(M21:N21)+AB21+AH21+S21 -> 114 | BD21: =SUM(G21:H21)+O21+P21 -> 70 | BE21: =SUM(I21:J21)+Q21+R21+AC21+AD21 -> 15 | BH21: =SUM(T21:V21)+AE21+AG21 -> 59 | BI21: =W21+AF21 -> 2 | BJ21: =X21+Z21+AI21 -> 26 | BK21: =Y21 -> 0 | BM21: 3
A22: =A21+1 -> 46252 | B22: 0 | C22: 520 | D22: 1156 | E22: 34 | F22: 1025 | G22: 52 | H22: 4 | I22: 0 | J22: 0 | K22: 383 | L22: 60 | M22: 256 | N22: 151 | O22: 68 | P22: 20 | Q22: 25 | R22: 11 | T22: 43 | U22: 27 | V22: 0 | W22: 14 | X22: 1 | Y22: 0 | Z22: 8 | AJ22: =SUM(B22:AI22) -> 3858 | AL22: =SUM(K22:L22)*2+SUM(M22:N22)*3+AH22+SUM(AA22:AD22)+17 -> 2124 | AM22: =SUM(E22:J22)+SUM(O22:R22)*3-999+999*3 -> 3485 | AN22: =SUM(C22:D22)*3+SUM(E22:H22)*2+SUM(I22:J22)*3+SUM(K22:N22)*2+SUM(O22:R22)+999 -> 10081 | AO22: 0 | AP22: 70 | AQ22: 0 | AS22: =SUM(AA22:AB22)+AH22+S22 -> 0 | AU22: =AJ22-AV22-AW22-AX22 -> 962 | AV22: 2888 | AW22: =AH22 -> 0 | AX22: =Z22+S22+AI22 -> 8 | AY22: =AG22 -> 0 | AZ22: 0 | BB22: =SUM(B22:D22)+K22+L22+AA22 -> 2119 | BC22: =SUM(E22:F22)+SUM(M22:N22)+AB22+AH22+S22 -> 1466 | BD22: =SUM(G22:H22)+O22+P22 -> 144 | BE22: =SUM(I22:J22)+Q22+R22+AC22+AD22 -> 36 | BH22: =SUM(T22:V22)+AE22+AG22 -> 70 | BI22: =W22+AF22 -> 14 | BJ22: =X22+Z22+AI22 -> 9 | BK22: =Y22 -> 0 | BM22: 16
A23: =A22+1 -> 46253 | B23: 0 | C23: 192 | D23: 105 | E23: 19 | F23: 549 | G23: 35 | H23: 1 | I23: 0 | J23: 0 | K23: 1 | L23: 5 | M23: 76 | N23: 22 | O23: 12 | P23: 16 | Q23: 6 | R23: 3 | T23: 7 | U23: 20 | V23: 0 | W23: 2 | X23: 0 | Y23: 0 | Z23: 8 | AH23: 7 | AJ23: =SUM(B23:AI23) -> 1086 | AL23: =SUM(K23:L23)*2+SUM(M23:N23)*3+AH23+SUM(AA23:AD23)+12 -> 325 | AM23: =SUM(E23:J23)+SUM(O23:R23)*3-536+536*3 -> 1787 | AN23: =SUM(C23:D23)*3+SUM(E23:H23)*2+SUM(I23:J23)*3+SUM(K23:N23)*2+SUM(O23:R23)+536 -> 2880 | AO23: 0 | AP23: 35 | AQ23: 0 | AS23: =SUM(AA23:AB23)+AH23+S23 -> 7 | AU23: =AJ23-AV23-AW23-AX23 -> 408 | AV23: 663 | AW23: =AH23 -> 7 | AX23: =Z23+S23+AI23 -> 8 | AY23: =AG23 -> 0 | AZ23: 0 | BB23: =SUM(B23:D23)+K23+L23+AA23 -> 303 | BC23: =SUM(E23:F23)+SUM(M23:N23)+AB23+AH23+S23 -> 673 | BD23: =SUM(G23:H23)+O23+P23 -> 64 | BE23: =SUM(I23:J23)+Q23+R23+AC23+AD23 -> 9 | BH23: =SUM(T23:V23)+AE23+AG23 -> 27 | BI23: =W23+AF23 -> 2 | BJ23: =X23+Z23+AI23 -> 8 | BK23: =Y23 -> 0 | BM23: 24
A24: =A23+1 -> 46254 | B24: 0 | C24: 214 | D24: 95 | E24: 10 | F24: 881 | G24: 8 | H24: 2 | I24: 0 | J24: 0 | K24: 4 | L24: 6 | M24: 71 | N24: 39 | O24: 11 | P24: 16 | Q24: 1 | R24: 7 | T24: 22 | U24: 6 | V24: 0 | W24: 3 | X24: 0 | Y24: 0 | Z24: 1 | AJ24: =SUM(B24:AI24) -> 1397 | AL24: =SUM(K24:L24)*2+SUM(M24:N24)*3+AH24+SUM(AA24:AD24) -> 350 | AM24: =SUM(E24:J24)+SUM(O24:R24)*3-570+570*3 -> 2146 | AN24: =SUM(C24:D24)*3+SUM(E24:H24)*2+SUM(I24:J24)*3+SUM(K24:N24)*2+SUM(O24:R24)+570 -> 3574 | AO24: 0 | AP24: 28 | AQ24: 0 | AS24: =SUM(AA24:AB24)+AH24+S24 -> 0 | AU24: =AJ24-AV24-AW24-AX24 -> 412 | AV24: 984 | AW24: =AH24 -> 0 | AX24: =Z24+S24+AI24 -> 1 | AY24: =AG24 -> 0 | AZ24: 0 | BB24: =SUM(B24:D24)+K24+L24+AA24 -> 319 | BC24: =SUM(E24:F24)+SUM(M24:N24)+AB24+AH24+S24 -> 1001 | BD24: =SUM(G24:H24)+O24+P24 -> 37 | BE24: =SUM(I24:J24)+Q24+R24+AC24+AD24 -> 8 | BH24: =SUM(T24:V24)+AE24+AG24 -> 28 | BI24: =W24+AF24 -> 3 | BJ24: =X24+Z24+AI24 -> 1 | BK24: =Y24 -> 0 | BM24: 13 | BN24: 20
A25: =A24+1 -> 46255 | B25: 0 | C25: 290 | D25: 86 | E25: 9 | F25: 534 | G25: 11 | H25: 1 | I25: 0 | J25: 0 | K25: 6 | L25: 7 | M25: 41 | N25: 22 | O25: 15 | P25: 13 | Q25: 7 | R25: 2 | T25: 13 | U25: 6 | V25: 0 | W25: 1 | X25: 0 | Y25: 0 | Z25: 3 | AJ25: =SUM(B25:AI25) -> 1067 | AL25: =SUM(K25:L25)*2+SUM(M25:N25)*3+AH25+SUM(AA25:AD25) -> 215 | AM25: =SUM(E25:J25)+SUM(O25:R25)*3-264+264*3 -> 1194 | AN25: =SUM(C25:D25)*3+SUM(E25:H25)*2+SUM(I25:J25)*3+SUM(K25:N25)*2+SUM(O25:R25)+264 -> 2691 | AO25: 0 | AP25: 43 | AQ25: 0 | AS25: =SUM(AA25:AB25)+AH25+S25 -> 0 | AU25: =AJ25-AV25-AW25-AX25 -> 328 | AV25: 736 | AW25: =AH25 -> 0 | AX25: =Z25+S25+AI25 -> 3 | AY25: =AG25 -> 0 | AZ25: 0 | BB25: =SUM(B25:D25)+K25+L25+AA25 -> 389 | BC25: =SUM(E25:F25)+SUM(M25:N25)+AB25+AH25+S25 -> 606 | BD25: =SUM(G25:H25)+O25+P25 -> 40 | BE25: =SUM(I25:J25)+Q25+R25+AC25+AD25 -> 9 | BH25: =SUM(T25:V25)+AE25+AG25 -> 19 | BI25: =W25+AF25 -> 1 | BJ25: =X25+Z25+AI25 -> 3 | BK25: =Y25 -> 0 | BM25: 11
A26: =A25+1 -> 46256 | AJ26: =SUM(B26:AI26) -> 0 | AL26: =SUM(K26:L26)*2+SUM(M26:N26)*3+AH26+SUM(AA26:AD26) -> 0 | AM26: =SUM(E26:J26)+SUM(O26:R26)*3 -> 0 | AN26: =SUM(C26:D26)*3+SUM(E26:H26)*2+SUM(I26:J26)*3+SUM(K26:N26)*2+SUM(O26:R26) -> 0 | AO26: 0 | AQ26: 0 | AS26: =SUM(AA26:AB26)+AH26+S26 -> 0 | AU26: =AJ26-AV26-AW26-AX26 -> 0 | AV26: 0 | AW26: =AH26 -> 0 | AX26: =Z26+S26+AI26 -> 0 | AY26: =AG26 -> 0 | AZ26: 0 | BB26: =SUM(B26:D26)+K26+L26+AA26 -> 0 | BC26: =SUM(E26:F26)+SUM(M26:N26)+AB26+AH26+S26 -> 0 | BD26: =SUM(G26:H26)+O26+P26 -> 0 | BE26: =SUM(I26:J26)+Q26+R26+AC26+AD26 -> 0 | BH26: =SUM(T26:V26)+AE26+AG26 -> 0 | BI26: =W26+AF26 -> 0 | BJ26: =X26+Z26+AI26 -> 0 | BK26: =Y26 -> 0
A27: =A26+1 -> 46257 | AJ27: =SUM(B27:AI27) -> 0 | AL27: =SUM(K27:L27)*2+SUM(M27:N27)*3+AH27+SUM(AA27:AD27) -> 0 | AM27: =SUM(E27:J27)+SUM(O27:R27)*3 -> 0 | AN27: =SUM(C27:D27)*3+SUM(E27:H27)*2+SUM(I27:J27)*3+SUM(K27:N27)*2+SUM(O27:R27) -> 0 | AO27: 0 | AQ27: 0 | AS27: =SUM(AA27:AB27)+AH27+S27 -> 0 | AU27: =AJ27-AV27-AW27-AX27 -> 0 | AV27: 0 | AW27: =AH27 -> 0 | AX27: =Z27+S27+AI27 -> 0 | AY27: =AG27 -> 0 | AZ27: 0 | BB27: =SUM(B27:D27)+K27+L27+AA27 -> 0 | BC27: =SUM(E27:F27)+SUM(M27:N27)+AB27+AH27+S27 -> 0 | BD27: =SUM(G27:H27)+O27+P27 -> 0 | BE27: =SUM(I27:J27)+Q27+R27+AC27+AD27 -> 0 | BH27: =SUM(T27:V27)+AE27+AG27 -> 0 | BI27: =W27+AF27 -> 0 | BJ27: =X27+Z27+AI27 -> 0 | BK27: =Y27 -> 0
A28: =A27+1 -> 46258 | B28: 0 | C28: 1440 | D28: 147 | E28: 48 | F28: 130 | G28: 18 | H28: 10 | I28: 0 | J28: 1 | K28: 7 | L28: 16 | M28: 101 | N28: 64 | O28: 14 | P28: 9 | Q28: 3 | R28: 2 | T28: 72 | U28: 18 | V28: 0 | W28: 7 | X28: 0 | Y28: 0 | Z28: 10 | AJ28: =SUM(B28:AI28) -> 2117 | AL28: =SUM(K28:L28)*2+SUM(M28:N28)*3+AH28+SUM(AA28:AD28) -> 541 | AM28: =SUM(E28:J28)+SUM(O28:R28)*3 -> 291 | AN28: =SUM(C28:D28)*3+SUM(E28:H28)*2+SUM(I28:J28)*3+SUM(K28:N28)*2+SUM(O28:R28) -> 5580 | AO28: 0 | AP28: 175 | AQ28: 0 | AS28: =SUM(AA28:AB28)+AH28+S28 -> 0 | AU28: =AJ28-AV28-AW28-AX28 -> 636 | AV28: 1471 | AW28: =AH28 -> 0 | AX28: =Z28+S28+AI28 -> 10 | AY28: =AG28 -> 0 | AZ28: 0 | BB28: =SUM(B28:D28)+K28+L28+AA28 -> 1610 | BC28: =SUM(E28:F28)+SUM(M28:N28)+AB28+AH28+S28 -> 343 | BD28: =SUM(G28:H28)+O28+P28 -> 51 | BE28: =SUM(I28:J28)+Q28+R28+AC28+AD28 -> 6 | BH28: =SUM(T28:V28)+AE28+AG28 -> 90 | BI28: =W28+AF28 -> 7 | BJ28: =X28+Z28+AI28 -> 10 | BK28: =Y28 -> 0 | BM28: 14
A29: =A28+1 -> 46259 | B29: 0 | C29: 214 | D29: 102 | E29: 7 | F29: 151 | G29: 39 | H29: 1 | I29: 0 | J29: 0 | K29: 7 | L29: 7 | M29: 54 | N29: 30 | O29: 13 | P29: 7 | Q29: 5 | R29: 5 | T29: 404 | U29: 11 | V29: 0 | W29: 4 | X29: 0 | Y29: 0 | Z29: 49 | AH29: 1 | AJ29: =SUM(B29:AI29) -> 1111 | AL29: =SUM(K29:L29)*2+SUM(M29:N29)*3+AH29+SUM(AA29:AD29) -> 281 | AM29: =SUM(E29:J29)+SUM(O29:R29)*3 -> 288 | AN29: =SUM(C29:D29)*3+SUM(E29:H29)*2+SUM(I29:J29)*3+SUM(K29:N29)*2+SUM(O29:R29) -> 1570 | AO29: 0 | AP29: 56 | AQ29: 0 | AS29: =SUM(AA29:AB29)+AH29+S29 -> 1 | AU29: =AJ29-AV29-AW29-AX29 -> 413 | AV29: 648 | AW29: =AH29 -> 1 | AX29: =Z29+S29+AI29 -> 49 | AY29: =AG29 -> 0 | AZ29: 0 | BB29: =SUM(B29:D29)+K29+L29+AA29 -> 330 | BC29: =SUM(E29:F29)+SUM(M29:N29)+AB29+AH29+S29 -> 243 | BD29: =SUM(G29:H29)+O29+P29 -> 60 | BE29: =SUM(I29:J29)+Q29+R29+AC29+AD29 -> 10 | BH29: =SUM(T29:V29)+AE29+AG29 -> 415 | BI29: =W29+AF29 -> 4 | BJ29: =X29+Z29+AI29 -> 49 | BK29: =Y29 -> 0 | BM29: 9
A30: =A29+1 -> 46260 | B30: 0 | C30: 252 | D30: 103 | E30: 14 | F30: 65 | G30: 14 | H30: 1 | I30: 0 | J30: 0 | K30: 10 | L30: 12 | M30: 51 | N30: 30 | O30: 4 | P30: 5 | Q30: 3 | R30: 2 | T30: 60 | U30: 9 | V30: 0 | W30: 1 | X30: 0 | Y30: 0 | Z30: 8 | AA30: 30 | AJ30: =SUM(B30:AI30) -> 674 | AL30: =SUM(K30:L30)*2+SUM(M30:N30)*3+AH30+SUM(AA30:AD30)+5-30 -> 292 | AM30: =SUM(E30:J30)+SUM(O30:R30)*3-49+49*3+30 -> 264 | AN30: =SUM(C30:D30)*3+SUM(E30:H30)*2+SUM(I30:J30)*3+SUM(K30:N30)*2+SUM(O30:R30)+49+32 -> 1554 | AO30: 0 | AP30: 16 | AQ30: 0 | AS30: =SUM(AA30:AB30)+AH30+S30 -> 30 | AU30: =AJ30-AV30-AW30-AX30 -> 431 | AV30: 235 | AW30: =AH30 -> 0 | AX30: =Z30+S30+AI30 -> 8 | AY30: =AG30 -> 0 | AZ30: 0 | BB30: =SUM(B30:D30)+K30+L30+AA30 -> 407 | BC30: =SUM(E30:F30)+SUM(M30:N30)+AB30+AH30+S30 -> 160 | BD30: =SUM(G30:H30)+O30+P30 -> 24 | BE30: =SUM(I30:J30)+Q30+R30+AC30+AD30 -> 5 | BH30: =SUM(T30:V30)+AE30+AG30 -> 69 | BI30: =W30+AF30 -> 1 | BJ30: =X30+Z30+AI30 -> 8 | BK30: =Y30 -> 0 | BM30: 38
A31: =A30+1 -> 46261 | B31: 0 | C31: 504 | D31: 103 | E31: 10 | F31: 136 | G31: 4 | H31: 2 | I31: 0 | J31: 0 | K31: 2 | L31: 10 | M31: 44 | N31: 29 | O31: 10 | P31: 10 | Q31: 0 | R31: 0 | T31: 89 | U31: 12 | V31: 0 | W31: 3 | X31: 0 | Y31: 0 | Z31: 3 | AE31: 6 | AJ31: =SUM(B31:AI31) -> 977 | AL31: =SUM(K31:L31)*2+SUM(M31:N31)*3+AH31+SUM(AA31:AD31) -> 243 | AM31: =SUM(E31:J31)+SUM(O31:R31)*3-123+123*3 -> 458 | AN31: =SUM(C31:D31)*3+SUM(E31:H31)*2+SUM(I31:J31)*3+SUM(K31:N31)*2+SUM(O31:R31)+123 -> 2438 | AO31: 0 | AP31: 36 | AQ31: 0 | AS31: =SUM(AA31:AB31)+AH31+S31 -> 0 | AU31: =AJ31-AV31-AX31-AW31-AY31 -> 377 | AV31: 597 | AW31: =AH31 -> 0 | AX31: =Z31+S31+AI31 -> 3 | AY31: =AG31 -> 0 | AZ31: 0 | BB31: =SUM(B31:D31)+K31+L31+AA31 -> 619 | BC31: =SUM(E31:F31)+SUM(M31:N31)+AB31+AH31+S31 -> 219 | BD31: =SUM(G31:H31)+O31+P31 -> 26 | BE31: =SUM(I31:J31)+Q31+R31+AC31+AD31 -> 0 | BH31: =SUM(T31:V31)+AE31+AG31 -> 107 | BI31: =W31+AF31 -> 3 | BJ31: =X31+Z31+AI31 -> 3 | BK31: =Y31 -> 0 | BM31: 11
A32: =A31+1 -> 46262 | B32: 0 | C32: 335 | D32: 113 | E32: 5 | F32: 90 | G32: 5 | H32: 3 | I32: 0 | J32: 0 | K32: 3 | L32: 3 | M32: 37 | N32: 24 | O32: 7 | P32: 6 | Q32: 4 | R32: 1 | T32: 64 | U32: 11 | V32: 0 | W32: 2 | X32: 0 | Y32: 0 | Z32: 2 | AE32: 10 | AJ32: =SUM(B32:AI32) -> 725 | AL32: =SUM(K32:L32)*2+SUM(M32:N32)*3+AH32+SUM(AA32:AD32) -> 195 | AM32: =SUM(E32:J32)+SUM(O32:R32)*3-76+76*3 -> 309 | AN32: =SUM(C32:D32)*3+SUM(E32:H32)*2+SUM(I32:J32)*3+SUM(K32:N32)*2+SUM(O32:R32)+76 -> 1778 | AO32: 0 | AP32: 17 | AQ32: 0 | AS32: =SUM(AA32:AB32)+AH32+S32 -> 0 | AU32: =AJ32-AV32-AX32-AW32-AY32 -> 367 | AV32: 356 | AW32: =AH32 -> 0 | AX32: =Z32+S32+AI32 -> 2 | AY32: =AG32 -> 0 | AZ32: 0 | BB32: =SUM(B32:D32)+K32+L32+AA32 -> 454 | BC32: =SUM(E32:F32)+SUM(M32:N32)+AB32+AH32+S32 -> 156 | BD32: =SUM(G32:H32)+O32+P32 -> 21 | BE32: =SUM(I32:J32)+Q32+R32+AC32+AD32 -> 5 | BH32: =SUM(T32:V32)+AE32+AG32 -> 85 | BI32: =W32+AF32 -> 2 | BJ32: =X32+Z32+AI32 -> 2 | BK32: =Y32 -> 0 | BM32: 23
A33: =A32+1 -> 46263 | AJ33: =SUM(B33:AI33) -> 0 | AL33: =SUM(K33:L33)*2+SUM(M33:N33)*3+AH33+SUM(AA33:AD33) -> 0 | AM33: =SUM(E33:J33)+SUM(O33:R33)*3 -> 0 | AN33: =SUM(C33:D33)*3+SUM(E33:H33)*2+SUM(I33:J33)*3+SUM(K33:N33)*2+SUM(O33:R33) -> 0 | AO33: 0 | AQ33: 0 | AS33: =SUM(AA33:AB33)+AH33+S33 -> 0 | AU33: =AJ33-AV33-AX33-AW33-AY33 -> 0 | AV33: 0 | AW33: =AH33 -> 0 | AX33: =Z33+S33+AI33 -> 0 | AZ33: 0 | BB33: =SUM(B33:D33)+K33+L33+AA33 -> 0 | BC33: =SUM(E33:F33)+SUM(M33:N33)+AB33+AH33+S33 -> 0 | BD33: =SUM(G33:H33)+O33+P33 -> 0 | BE33: =SUM(I33:J33)+Q33+R33+AC33+AD33 -> 0 | BH33: =SUM(T33:V33)+AE33+AG33 -> 0 | BI33: =W33+AF33 -> 0 | BJ33: =X33+Z33+AI33 -> 0 | BK33: =Y33 -> 0
A34: =A33+1 -> 46264 | AJ34: =SUM(B34:AI34) -> 0 | AL34: =SUM(K34:L34)*2+SUM(M34:N34)*3+AH34+SUM(AA34:AD34) -> 0 | AM34: =SUM(E34:J34)+SUM(O34:R34)*3 -> 0 | AN34: =SUM(C34:D34)*3+SUM(E34:H34)*2+SUM(I34:J34)*3+SUM(K34:N34)*2+SUM(O34:R34) -> 0 | AO34: 0 | AQ34: 0 | AS34: =SUM(AA34:AB34)+AH34+S34 -> 0 | AU34: =AJ34-AV34-AX34-AW34-AY34 -> 0 | AV34: 0 | AW34: =AH34 -> 0 | AX34: =Z34+S34+AI34 -> 0 | AZ34: 0 | BB34: =SUM(B34:D34)+K34+L34+AA34 -> 0 | BC34: =SUM(E34:F34)+SUM(M34:N34)+AB34+AH34+S34 -> 0 | BD34: =SUM(G34:H34)+O34+P34 -> 0 | BE34: =SUM(I34:J34)+Q34+R34+AC34+AD34 -> 0 | BH34: =SUM(T34:V34)+AE34+AG34 -> 0 | BI34: =W34+AF34 -> 0 | BJ34: =X34+Z34+AI34 -> 0 | BK34: =Y34 -> 0
A35: =A34+1 -> 46265 | B35: 0 | C35: 1520 | D35: 415 | E35: 56 | F35: 58 | G35: 15 | H35: 0 | I35: 0 | J35: 0 | K35: 18 | L35: 36 | M35: 87 | N35: 47 | O35: 22 | P35: 20 | Q35: 8 | R35: 4 | T35: 342 | U35: 21 | V35: 0 | W35: 4 | X35: 0 | Y35: 0 | Z35: 564 | AE35: 5 | AJ35: =SUM(B35:AI35) -> 3242 | AL35: =SUM(K35:L35)*2+SUM(M35:N35)*3+AH35+SUM(AA35:AD35) -> 510 | AM35: =SUM(E35:J35)+SUM(O35:R35)*3 -> 291 | AN35: =SUM(C35:D35)*3+SUM(E35:H35)*2+SUM(I35:J35)*3+SUM(K35:N35)*2+SUM(O35:R35) -> 6493 | AO35: 0 | AQ35: 0 | AS35: =SUM(AA35:AB35)+AH35+S35 -> 0 | AU35: =AJ35-AV35-AX35-AW35-AY35 -> 2678 | AV35: 0 | AW35: =AH35 -> 0 | AX35: =Z35+S35+AI35 -> 564 | AY35: =AG35 -> 0 | AZ35: 0 | BB35: =SUM(B35:D35)+K35+L35+AA35 -> 1989 | BC35: =SUM(E35:F35)+SUM(M35:N35)+AB35+AH35 -> 248 | BD35: =SUM(G35:H35)+O35+P35 -> 57 | BE35: =SUM(I35:J35)+Q35+R35+AC35+AD35 -> 12 | BH35: =SUM(T35:V35)+AE35+AG35 -> 368 | BI35: =W35+AF35 -> 4 | BJ35: =X35+Z35+AI35 -> 564 | BK35: =Y35 -> 0 | BM35: 22
A36: 합 계 | B36: =SUM(B5:B35) -> 0 | C36: =SUM(C5:C35) -> 12851 | D36: =SUM(D5:D35) -> 4392 | E36: =SUM(E5:E35) -> 479 | F36: =SUM(F5:F35) -> 8810 | G36: =SUM(G5:G35) -> 372 | H36: =SUM(H5:H35) -> 49 | I36: =SUM(I5:I35) -> 0 | ... R36: =SUM(R5:R35) -> 70 | S36: =SUM(S5:S32) -> 0 | T36: =SUM(T5:T35) -> 4074 | U36: =SUM(U5:U35) -> 344 | V36: =SUM(V5:V35) -> 0 | W36: =SUM(W5:W35) -> 106 | X36: =SUM(X5:X35) -> 3 | Y36: =SUM(Y5:Y35) -> 0 | Z36: =SUM(Z5:Z35) -> 1154 | AA36: =SUM(AA5:AA35) -> 30 | ... AJ36: =SUM(AJ5:AJ35) -> 39021 | AL36: =SUM(AL5:AL35) -> 26971 | AM36: =SUM(AM5:AM35) -> 27917 | AN36: =SUM(AN5:AN35) -> 81352 | AO36: =SUM(AO5:AO35) -> 0 | AP36: =SUM(AP5:AP35) -> 1104 | AQ36: =SUM(AQ5:AQ35) -> 27 | AR36: =SUM(AR5:AR35) -> 0 | AS36: =SUM(AS5:AS35) -> 42 | AU36: =SUM(AU5:AU35) -> 12473 | AV36: =SUM(AV5:AV35) -> 25382 | AW36: =SUM(AW5:AW35) -> 12 | AX36: =SUM(AX5:AX35) -> 1154 | AY36: =SUM(AY5:AY35) -> 0 | AZ36: =SUM(AZ5:AZ35) -> 0 | BB36: =SUM(BB5:BB35) -> 19378 | BC36: =SUM(BC5:BC35) -> 12537 | BD36: =SUM(BD5:BD35) -> 1213 | BE36: =SUM(BE5:BE35) -> 183 | BF36: =SUM(BF5:BF35) -> 0 | BG36: =SUM(BG5:BG35) -> 0 | BH36: =SUM(BH5:BH35) -> 4447 | BI36: =SUM(BI5:BI35) -> 106 | ... BK36: =SUM(BK5:BK35) -> 0 | BM36: =SUM(BM5:BM35) -> 422 | BN36: =SUM(BN5:BN35) -> 27
AL37: ※ 아이스팩(중), 신선테이핑 작업료 - 상온 부직포 선물세트 건수 제외
AL38: ※ PCM - 냉동 부직포 선물세트 건수 포함

Sheet 홈쇼핑
B1: CJ온스타일 | V1: 공영쇼핑 | AA1: NS홈쇼핑 | AY1: CJ온스타일,공영은 작업비만 | BB1: NS는 작업비+택배비까지 청구
A2: ㈜농협목우촌 | B2: 홈쇼핑_아이스박스_1호 냉장 | C2: 홈쇼핑_아이스박스_1호 냉동 | D2: 홈쇼핑_아이스박스_T135 냉장 | E2: 홈쇼핑_아이스박스_T135 냉장 | F2: 홈쇼핑_아이스박스_2호 냉장 | G2: 홈쇼핑_아이스박스_2호 냉동 | H2: 홈쇼핑_아이스박스_3호 냉장 | I2: 홈쇼핑_아이스박스_3호 냉동 | J2: 홈쇼핑_아이스박스_4호 냉장 | K2: 홈쇼핑_아이스박스_4호 냉동 | L2: 홈쇼핑_아이스박스_5호 냉장 | M2: 홈쇼핑_아이스박스_5호 냉동 | N2: 홈쇼핑_아이스박스_6호 냉장 | O2: 홈쇼핑_아이스박스_6호 냉동 | P2: 홈쇼핑_종이박스_1호 | Q2: 홈쇼핑_종이박스_2호 | R2: 홈쇼핑_종이박스_4호 | S2: 홈쇼핑_종이박스_5호 | T2: 총수량 | V2: 홈쇼핑_아이스박스_3호 냉장 | W2: 홈쇼핑_종이박스_2호 | X2: 일반_종이박스_2호 (두껍) | Y2: 총수량 | AA2: 홈쇼핑_아이스박스_2k 냉장 | AB2: 홈쇼핑_아이스박스_1호 냉장 | AC2: 홈쇼핑_아이스박스_1호 냉동 | AD2: 홈쇼핑_아이스박스_T135 냉장 | AE2: 홈쇼핑_아이스박스_T135 냉동 | AF2: 홈쇼핑_아이스박스_2호 냉장 | AG2: 홈쇼핑_아이스박스_2호 냉동 | AH2: 홈쇼핑_아이스박스_3호 냉장 | AI2: 홈쇼핑_아이스박스_3호 냉동 | AJ2: 홈쇼핑_아이스박스_4호 냉장 | AK2: 홈쇼핑_아이스박스_4호 냉동 | AL2: 홈쇼핑_아이스박스_5호 냉장 | AM2: 홈쇼핑_아이스박스_5호 냉동 | AN2: 홈쇼핑_아이스박스_6호 냉장 | AO2: 홈쇼핑_아이스박스_6호 냉동 | AP2: 홈쇼핑_종이박스_1호 | AQ2: 홈쇼핑_종이박스_2호 | AR2: 총수량 | AT2: 아이스팩_500g | AU2: 아이스팩_1000g | AV2: PCM | AW2: 드라이아이스 | AY2: 작업료_세트/홈쇼핑 | AZ2: 작업료_세트/홈쇼핑_해체 | BA2: 저온_택배비_극소 | BB2: 저온_택배비_소 | BC2: 상온_택배비_극소 | BD2: 작업료_완충제포장 | BE2: 작업료_완충제인입 | BF2: 작업료_부직포가방 | BH2: 특이사항
A3: 사이즈 | B3: 극소 | C3: 극소 | D3: 극소 | E3: 극소 | F3: 소 | G3: 소 | H3: 소 | I3: 소 | J3: 중 | K3: 중 | L3: 중 | M3: 중 | N3: 대 | O3: 대 | P3: 극소 | Q3: 극소 | R3: 중 | S3: 대 | V3: 소 | W3: 극소 | X3: 극소 | AA3: 극소 | AB3: 극소 | AC3: 극소 | AD3: 극소 | AE3: 극소 | AF3: 소 | AG3: 소 | AH3: 소 | AI3: 소 | AJ3: 중 | AK3: 중 | AL3: 중 | AM3: 중 | AN3: 대 | AO3: 대 | AP3: 극소 | AQ3: 극소 | BA3: 극소 | BB3: 소 | BC3: 극소
A4: 46235 | T4: =SUM(B4:S4) -> 0 | Y4: =SUM(V4:X4) -> 0 | AR4: =SUM(AA4:AQ4) -> 0 | AT4: =N(C4)*2+N(AC4)*2+N(AE4)*2+N(G4)*3+N(I4)*3+N(AG4)*3+N(AI4)*3+N(F4)+N(H4)+N(J4)+N(L4)+N(AF4)+N(AH4)+N(AJ4)+N(AL4)+N(N4)*2+N(AN4)*2 -> 0 | AU4: =N(F4)+N(H4)+N(J4)+N(K4)*3+N(L4)+N(M4)*3+N(N4)+N(O4)*3+N(AF4)+N(AH4)+N(AJ4)+N(AK4)*3+N(AL4)+N(AM4)*3+N(AN4)+N(AO4)*3+V4*2 -> 0 | AV4: =N(AA4)+N(B4)*2+N(D4)*2+N(E4)*2+N(AB4)*2+N(AD4)*2+N(C4)*2+N(AC4)*2+N(AE4)*2+N(G4)*2+N(I4)*2+N(AG4)*2+N(AI4)*2+N(K4)+N(M4)+N(O4)+N(AK4)+N(AM4)+N(AO4) -> 0 | AW4: 0 | AY4: =T4+Y4+AR4 -> 0 | BA4: =SUM(AA4:AE4) -> 0 | BB4: =SUM(AF4:AI4) -> 0 | BC4: =SUM(AP4:AQ4) -> 0
A5: =A4+1 -> 46236 | T5: =SUM(B5:S5) -> 0 | Y5: =SUM(V5:X5) -> 0 | AR5: =SUM(AA5:AQ5) -> 0 | AT5: =N(B5)*2+N(C5)*2+N(D5)*2+N(E5)*2+N(G5)*3+N(I5)*3+N(N5)+N(AA5)+N(AB5)*2+N(AC5)*2+N(AD5)*2+N(AE5)*2+N(AG5)*3+N(AI5)*3+N(AN5) -> 0 | AU5: =N(F5)+N(H5)+N(J5)+N(K5)*3+N(L5)+N(M5)*3+N(N5)+N(O5)*3+N(AF5)+N(AH5)+N(AJ5)+N(AK5)*3+N(AL5)+N(AM5)*3+N(AN5)+N(AO5)*3+V5*2 -> 0 | AV5: =N(AA5)+N(B5)*2+N(D5)*2+N(E5)*2+N(AB5)*2+N(AD5)*2+N(C5)*2+N(AC5)*2+N(AE5)*2+N(G5)*2+N(I5)*2+N(AG5)*2+N(AI5)*2+N(K5)+N(M5)+N(O5)+N(AK5)+N(AM5)+N(AO5) -> 0 | AW5: 0 | AY5: =T5+Y5+AR5 -> 0 | BA5: =SUM(AA5:AE5) -> 0 | BB5: =SUM(AF5:AI5) -> 0 | BC5: =SUM(AP5:AQ5) -> 0
A6: =A5+1 -> 46237 | C6: 1 | T6: =SUM(B6:S6) -> 1 | V6: 4 | Y6: =SUM(V6:X6) -> 4 | AD6: 1 | AI6: 2 | AR6: =SUM(AA6:AQ6) -> 3 | AT6: =N(B6)*2+N(C6)*2+N(D6)*2+N(E6)*2+N(G6)*3+N(I6)*3+N(N6)+N(AA6)+N(AB6)*2+N(AC6)*2+N(AD6)*2+N(AE6)*2+N(AG6)*3+N(AI6)*3+N(AN6) -> 10 | AU6: =N(F6)+N(H6)+N(J6)+N(K6)*3+N(L6)+N(M6)*3+N(N6)+N(O6)*3+N(AF6)+N(AH6)+N(AJ6)+N(AK6)*3+N(AL6)+N(AM6)*3+N(AN6)+N(AO6)*3+V6*2 -> 8 | AV6: =N(AA6)+N(B6)*2+N(D6)*2+N(E6)*2+N(AB6)*2+N(AD6)*2+N(C6)*2+N(AC6)*2+N(AE6)*2+N(G6)*2+N(I6)*2+N(AG6)*2+N(AI6)*2+N(K6)+N(M6)+N(O6)+N(AK6)+N(AM6)+N(AO6) -> 8 | AW6: 0 | AY6: =T6+Y6+AR6 -> 8 | BA6: =SUM(AA6:AE6) -> 1 | BB6: =SUM(AF6:AI6) -> 2 | BC6: =SUM(AP6:AQ6) -> 0
A7: =A6+1 -> 46238 | B7: 1 | T7: =SUM(B7:S7) -> 1 | V7: 2 | Y7: =SUM(V7:X7) -> 2 | AR7: =SUM(AA7:AQ7) -> 0 | AT7: =N(B7)*2+N(C7)*2+N(D7)*2+N(E7)*2+N(G7)*3+N(I7)*3+N(N7)+N(AA7)+N(AB7)*2+N(AC7)*2+N(AD7)*2+N(AE7)*2+N(AG7)*3+N(AI7)*3+N(AN7) -> 2 | AU7: =N(F7)+N(H7)+N(J7)+N(K7)*3+N(L7)+N(M7)*3+N(N7)+N(O7)*3+N(AF7)+N(AH7)+N(AJ7)+N(AK7)*3+N(AL7)+N(AM7)*3+N(AN7)+N(AO7)*3+V7*2 -> 4 | AV7: =N(AA7)+N(B7)*2+N(D7)*2+N(E7)*2+N(AB7)*2+N(AD7)*2+N(C7)*2+N(AC7)*2+N(AE7)*2+N(G7)*2+N(I7)*2+N(AG7)*2+N(AI7)*2+N(K7)+N(M7)+N(O7)+N(AK7)+N(AM7)+N(AO7) -> 2 | AW7: 0 | AY7: =T7+Y7+AR7 -> 3 | BA7: =SUM(AA7:AE7) -> 0 | BB7: =SUM(AF7:AI7) -> 0 | BC7: =SUM(AP7:AQ7) -> 0
A8: =A7+1 -> 46239 | E8: 5 | T8: =SUM(B8:S8) -> 5 | V8: 1 | W8: 1 | Y8: =SUM(V8:X8) -> 2 | AD8: 1 | AR8: =SUM(AA8:AQ8) -> 1 | AT8: =N(B8)*2+N(C8)*2+N(D8)*2+N(E8)*2+N(G8)*3+N(I8)*3+N(N8)+N(AA8)+N(AB8)*2+N(AC8)*2+N(AD8)*2+N(AE8)*2+N(AG8)*3+N(AI8)*3+N(AN8) -> 12 | AU8: =N(F8)+N(H8)+N(J8)+N(K8)*3+N(L8)+N(M8)*3+N(N8)+N(O8)*3+N(AF8)+N(AH8)+N(AJ8)+N(AK8)*3+N(AL8)+N(AM8)*3+N(AN8)+N(AO8)*3+V8*2 -> 2 | AV8: =N(AA8)+N(B8)*2+N(D8)*2+N(E8)*2+N(AB8)*2+N(AD8)*2+N(C8)*2+N(AC8)*2+N(AE8)*2+N(G8)*2+N(I8)*2+N(AG8)*2+N(AI8)*2+N(K8)+N(M8)+N(O8)+N(AK8)+N(AM8)+N(AO8) -> 12 | AW8: 0 | AY8: =T8+Y8+AR8 -> 8 | BA8: =SUM(AA8:AE8) -> 1 | BB8: =SUM(AF8:AI8) -> 0 | BC8: =SUM(AP8:AQ8) -> 0
A9: =A8+1 -> 46240 | T9: =SUM(B9:S9) -> 0 | V9: 1 | Y9: =SUM(V9:X9) -> 1 | AI9: 1 | AR9: =SUM(AA9:AQ9) -> 1 | AT9: =N(B9)*2+N(C9)*2+N(D9)*2+N(E9)*2+N(G9)*3+N(I9)*3+N(N9)+N(AA9)+N(AB9)*2+N(AC9)*2+N(AD9)*2+N(AE9)*2+N(AG9)*3+N(AI9)*3+N(AN9) -> 3 | AU9: =N(F9)+N(H9)+N(J9)+N(K9)*3+N(L9)+N(M9)*3+N(N9)+N(O9)*3+N(AF9)+N(AH9)+N(AJ9)+N(AK9)*3+N(AL9)+N(AM9)*3+N(AN9)+N(AO9)*3+V9*2 -> 2 | AV9: =N(AA9)+N(B9)*2+N(D9)*2+N(E9)*2+N(AB9)*2+N(AD9)*2+N(C9)*2+N(AC9)*2+N(AE9)*2+N(G9)*2+N(I9)*2+N(AG9)*2+N(AI9)*2+N(K9)+N(M9)+N(O9)+N(AK9)+N(AM9)+N(AO9) -> 2 | AW9: 0 | AY9: =T9+Y9+AR9 -> 2 | BA9: =SUM(AA9:AE9) -> 0 | BB9: =SUM(AF9:AI9) -> 1 | BC9: =SUM(AP9:AQ9) -> 0
A10: =A9+1 -> 46241 | T10: =SUM(B10:S10) -> 0 | Y10: =SUM(V10:X10) -> 0 | AA10: 2 | AP10: 1 | AR10: =SUM(AA10:AQ10) -> 3 | AT10: =N(B10)*2+N(C10)*2+N(D10)*2+N(E10)*2+N(G10)*3+N(I10)*3+N(N10)+N(AA10)+N(AB10)*2+N(AC10)*2+N(AD10)*2+N(AE10)*2+N(AG10)*3+N(AI10)*3+N(AN10) -> 2 | AU10: =N(F10)+N(H10)+N(J10)+N(K10)*3+N(L10)+N(M10)*3+N(N10)+N(O10)*3+N(AF10)+N(AH10)+N(AJ10)+N(AK10)*3+N(AL10)+N(AM10)*3+N(AN10)+N(AO10)*3+V10*2 -> 0 | AV10: =N(AA10)+N(B10)*2+N(D10)*2+N(E10)*2+N(AB10)*2+N(AD10)*2+N(C10)*2+N(AC10)*2+N(AE10)*2+N(G10)*2+N(I10)*2+N(AG10)*2+N(AI10)*2+N(K10)+N(M10)+N(O10)+N(AK10)+N(AM10)+N(AO10) -> 2 | AW10: 0 | AY10: =T10+Y10+AR10 -> 3 | BA10: =SUM(AA10:AE10) -> 2 | BB10: =SUM(AF10:AI10) -> 0 | BC10: =SUM(AP10:AQ10) -> 1
A11: =A10+1 -> 46242 | T11: =SUM(B11:S11) -> 0 | Y11: =SUM(V11:X11) -> 0 | AR11: =SUM(AA11:AQ11) -> 0 | AT11: =N(B11)*2+N(C11)*2+N(D11)*2+N(E11)*2+N(G11)*3+N(I11)*3+N(N11)+N(AA11)+N(AB11)*2+N(AC11)*2+N(AD11)*2+N(AE11)*2+N(AG11)*3+N(AI11)*3+N(AN11) -> 0 | AU11: =N(F11)+N(H11)+N(J11)+N(K11)*3+N(L11)+N(M11)*3+N(N11)+N(O11)*3+N(AF11)+N(AH11)+N(AJ11)+N(AK11)*3+N(AL11)+N(AM11)*3+N(AN11)+N(AO11)*3+V11*2 -> 0 | AV11: =N(AA11)+N(B11)*2+N(D11)*2+N(E11)*2+N(AB11)*2+N(AD11)*2+N(C11)*2+N(AC11)*2+N(AE11)*2+N(G11)*2+N(I11)*2+N(AG11)*2+N(AI11)*2+N(K11)+N(M11)+N(O11)+N(AK11)+N(AM11)+N(AO11) -> 0 | AW11: 0 | AY11: =T11+Y11+AR11 -> 0 | BA11: =SUM(AA11:AE11) -> 0 | BB11: =SUM(AF11:AI11) -> 0 | BC11: =SUM(AP11:AQ11) -> 0
A12: =A11+1 -> 46243 | T12: =SUM(B12:S12) -> 0 | Y12: =SUM(V12:X12) -> 0 | AR12: =SUM(AA12:AQ12) -> 0 | AT12: =N(B12)*2+N(C12)*2+N(D12)*2+N(E12)*2+N(G12)*3+N(I12)*3+N(N12)+N(AA12)+N(AB12)*2+N(AC12)*2+N(AD12)*2+N(AE12)*2+N(AG12)*3+N(AI12)*3+N(AN12) -> 0 | AU12: =N(F12)+N(H12)+N(J12)+N(K12)*3+N(L12)+N(M12)*3+N(N12)+N(O12)*3+N(AF12)+N(AH12)+N(AJ12)+N(AK12)*3+N(AL12)+N(AM12)*3+N(AN12)+N(AO12)*3+V12*2 -> 0 | AV12: =N(AA12)+N(B12)*2+N(D12)*2+N(E12)*2+N(AB12)*2+N(AD12)*2+N(C12)*2+N(AC12)*2+N(AE12)*2+N(G12)*2+N(I12)*2+N(AG12)*2+N(AI12)*2+N(K12)+N(M12)+N(O12)+N(AK12)+N(AM12)+N(AO12) -> 0 | AW12: 0 | AY12: =T12+Y12+AR12 -> 0 | BA12: =SUM(AA12:AE12) -> 0 | BB12: =SUM(AF12:AI12) -> 0 | BC12: =SUM(AP12:AQ12) -> 0
A13: =A12+1 -> 46244 | T13: =SUM(B13:S13) -> 0 | V13: 3 | Y13: =SUM(V13:X13) -> 3 | AD13: 3 | AI13: 1 | AR13: =SUM(AA13:AQ13) -> 4 | AT13: =N(B13)*2+N(C13)*2+N(D13)*2+N(E13)*2+N(G13)*3+N(I13)*3+N(N13)+N(AA13)+N(AB13)*2+N(AC13)*2+N(AD13)*2+N(AE13)*2+N(AG13)*3+N(AI13)*3+N(AN13) -> 9 | AU13: =N(F13)+N(H13)+N(J13)+N(K13)*3+N(L13)+N(M13)*3+N(N13)+N(O13)*3+N(AF13)+N(AH13)+N(AJ13)+N(AK13)*3+N(AL13)+N(AM13)*3+N(AN13)+N(AO13)*3+V13*2 -> 6 | AV13: =N(AA13)+N(B13)*2+N(D13)*2+N(E13)*2+N(AB13)*2+N(AD13)*2+N(C13)*2+N(AC13)*2+N(AE13)*2+N(G13)*2+N(I13)*2+N(AG13)*2+N(AI13)*2+N(K13)+N(M13)+N(O13)+N(AK13)+N(AM13)+N(AO13) -> 8 | AW13: 0 | AY13: =T13+Y13+AR13 -> 7 | BA13: =SUM(AA13:AE13) -> 3 | BB13: =SUM(AF13:AI13) -> 1 | BC13: =SUM(AP13:AQ13) -> 0
A14: =A13+1 -> 46245 | C14: 2 | T14: =SUM(B14:S14) -> 2 | V14: 2 | W14: 2 | Y14: =SUM(V14:X14) -> 4 | AD14: 2 | AR14: =SUM(AA14:AQ14) -> 2 | AT14: =N(B14)*2+N(C14)*2+N(D14)*2+N(E14)*2+N(G14)*3+N(I14)*3+N(N14)+N(AA14)+N(AB14)*2+N(AC14)*2+N(AD14)*2+N(AE14)*2+N(AG14)*3+N(AI14)*3+N(AN14) -> 8 | AU14: =N(F14)+N(H14)+N(J14)+N(K14)*3+N(L14)+N(M14)*3+N(N14)+N(O14)*3+N(AF14)+N(AH14)+N(AJ14)+N(AK14)*3+N(AL14)+N(AM14)*3+N(AN14)+N(AO14)*3+V14*2 -> 4 | AV14: =N(AA14)+N(B14)*2+N(D14)*2+N(E14)*2+N(AB14)*2+N(AD14)*2+N(C14)*2+N(AC14)*2+N(AE14)*2+N(G14)*2+N(I14)*2+N(AG14)*2+N(AI14)*2+N(K14)+N(M14)+N(O14)+N(AK14)+N(AM14)+N(AO14) -> 8 | AW14: 0 | AY14: =T14+Y14+AR14 -> 8 | BA14: =SUM(AA14:AE14) -> 2 | BB14: =SUM(AF14:AI14) -> 0 | BC14: =SUM(AP14:AQ14) -> 0
A15: =A14+1 -> 46246 | C15: 1 | T15: =SUM(B15:S15) -> 1 | Y15: =SUM(V15:X15) -> 0 | AI15: 4 | AR15: =SUM(AA15:AQ15) -> 4 | AT15: =N(C15)*2+N(AC15)*2+N(AE15)*2+(N(G15)+N(I15)+N(AG15)+N(AI15))*3 -> 14 | AU15: =N(F15)+N(H15)+N(J15)+N(K15)*3+N(L15)+N(M15)*3+N(N15)+N(O15)*3+N(AF15)+N(AH15)+N(AJ15)+N(AK15)*3+N(AL15)+N(AM15)*3+N(AN15)+N(AO15)*3+V15*2 -> 0 | AV15: =(N(B15)+N(D15)+N(E15)+N(AB15)+N(AD15))*3+(N(F15)+N(H15)+N(J15)+N(L15)+N(AF15)+N(AH15)+N(AJ15)+N(AL15))*2+(N(N15)+N(AN15))*3+(N(C15)+N(AC15)+N(AE15)+N(G15)+N(I15)+N(AG15)+N(AI15))*2+N(K15)+N(M15)+N(O15)+N(AK15)+N(AM15)+N(AO15) -> 10 | AW15: 0 | AY15: =T15+Y15+AR15 -> 5 | BA15: =SUM(AA15:AE15) -> 0 | BB15: =SUM(AF15:AI15) -> 4 | BC15: =SUM(AP15:AQ15) -> 0
